Workbook

Sheet 1 QZ JUNHO
O4: 0.5
I5: =SUBTOTAL(9,I7:I51) -> 0 | J5: =SUBTOTAL(9,J7:J51) -> 12877.39 | K5: =SUBTOTAL(9,K7:K51) -> 75550 | L5: =SUBTOTAL(9,L7:L51) -> 19148.33 | M5: =SUBTOTAL(9,M7:M51) -> 0 | N5: =SUBTOTAL(9,N7:N51) -> 43524.28 | O5: =SUBTOTAL(9,O7:O51) -> 0 | P5: =SUBTOTAL(9,P7:P51) -> 43524.28 | ... R5: =SUBTOTAL(9,R7:R51) -> 32140.09
B6: COLABORADOR | C6: CPF | D6: GESTÃO DE CAIXA | E6: REGIONAL | F6: CENTRO DE CUSTO | G6: GESTOR | H6: DIRETOR | I6: SALDO REEMBOLSAR | J6: SALDO FINAL | K6: 1ª QZ | L6: SALDO CARTAO | M6: Adiantamento | N6: CARGA PARCIAL | O6: REEMBOLSO | P6: Carga CORRETA | Q6: Carga RECEBIDA | R6: Carga DIFERENÇA | S6: STATUS DO CARTÃO
B7: SILVIO VINICIUS PINHEIRO GOES | C7: 51182084168 | D7: ANDREY | E7: REGIONAL CO | F7: CLARO CO | G7: ANGELICA SOARES | H7: ROGERIO SCATAMBULO | I7: 0 | J7: 0 | K7: 5700 | L7: 0 | N7: =Tabela1[[#This Row],[1ª QZ]]-Tabela1[[#This Row],[SALDO FINAL]]-Tabela1[[#This Row],[SALDO CARTAO]]-Tabela1[[#This Row],[Adiantamento ]] -> 5700 | O7: =Tabela1[[#This Row],[SALDO REEMBOLSAR]]*$O$4 -> 0 | P7: =IF(Tabela1[[#This Row],[CARGA PARCIAL]]<0,0,Tabela1[[#This Row],[CARGA PARCIAL]])+Tabela1[[#This Row],[REEMBOLSO]] -> 5700 | Q7: 298.08 | R7: =Tabela1[[#This Row],[Carga CORRETA]]-Tabela1[[#This Row],[Carga RECEBIDA]] -> 5401.92 | S7: =_xlfn.XLOOKUP(Tabela1[[#This Row],[COLABORADOR]],'STATUS CARTAO'!D:D,'STATUS CARTAO'!G:G) -> Cartão ativo
B8: FLAVIO FERNANDES DOS REIS LIMA | C8: 01767960107 | D8: ANDREY | E8: REGIONAL CO | F8: TELEFONICA CO | G8: ANGELICA SOARES | H8: ROGERIO SCATAMBULO | I8: 0 | J8: 2170.23 | K8: 5700 | L8: 93 | N8: =Tabela1[[#This Row],[1ª QZ]]-Tabela1[[#This Row],[SALDO FINAL]]-Tabela1[[#This Row],[SALDO CARTAO]]-Tabela1[[#This Row],[Adiantamento ]] -> 3436.77 | O8: =Tabela1[[#This Row],[SALDO REEMBOLSAR]]*$O$4 -> 0 | P8: =IF(Tabela1[[#This Row],[CARGA PARCIAL]]<0,0,Tabela1[[#This Row],[CARGA PARCIAL]])+Tabela1[[#This Row],[REEMBOLSO]] -> 3436.77 | Q8: 0 | R8: =Tabela1[[#This Row],[Carga CORRETA]]-Tabela1[[#This Row],[Carga RECEBIDA]] -> 3436.77 | S8: =_xlfn.XLOOKUP(Tabela1[[#This Row],[COLABORADOR]],'STATUS CARTAO'!D:D,'STATUS CARTAO'!G:G) -> Cartão ativo
B9: WALTER DE CAMPOS NUNES NETO | C9: 99114160030 | D9: STEFANI | E9: REGIONAL CLARO INFRA SUL | F9: CLARO INFRA RS | G9: BRUNO EDUARDO | H9: EVERSON GAIDSTIECHI | I9: 0 | J9: 0 | K9: 5600 | L9: 2789.7 | N9: =Tabela1[[#This Row],[1ª QZ]]-Tabela1[[#This Row],[SALDO FINAL]]-Tabela1[[#This Row],[SALDO CARTAO]]-Tabela1[[#This Row],[Adiantamento ]] -> 2810.3 | O9: =Tabela1[[#This Row],[SALDO REEMBOLSAR]]*$O$4 -> 0 | P9: =IF(Tabela1[[#This Row],[CARGA PARCIAL]]<0,0,Tabela1[[#This Row],[CARGA PARCIAL]])+Tabela1[[#This Row],[REEMBOLSO]] -> 2810.3 | Q9: 0 | R9: =Tabela1[[#This Row],[Carga CORRETA]]-Tabela1[[#This Row],[Carga RECEBIDA]] -> 2810.3 | S9: =_xlfn.XLOOKUP(Tabela1[[#This Row],[COLABORADOR]],'STATUS CARTAO'!D:D,'STATUS CARTAO'!G:G) -> Cartão ativo
B10: CAIOS VINICIUS NUNES BROERING | C10: 07053418952 | D10: STEFANI | E10: REGIONAL CLARO INFRA SUL | F10: CLARO INFRA SC | G10: BRUNO EDUARDO | H10: EVERSON GAIDSTIECHI | I10: 0 | J10: 263.7 | K10: 2520 | L10: 90.56 | N10: =Tabela1[[#This Row],[1ª QZ]]-Tabela1[[#This Row],[SALDO FINAL]]-Tabela1[[#This Row],[SALDO CARTAO]]-Tabela1[[#This Row],[Adiantamento ]] -> 2165.74 | O10: =Tabela1[[#This Row],[SALDO REEMBOLSAR]]*$O$4 -> 0 | P10: =IF(Tabela1[[#This Row],[CARGA PARCIAL]]<0,0,Tabela1[[#This Row],[CARGA PARCIAL]])+Tabela1[[#This Row],[REEMBOLSO]] -> 2165.74 | Q10: 0 | R10: =Tabela1[[#This Row],[Carga CORRETA]]-Tabela1[[#This Row],[Carga RECEBIDA]] -> 2165.74 | S10: =_xlfn.XLOOKUP(Tabela1[[#This Row],[COLABORADOR]],'STATUS CARTAO'!D:D,'STATUS CARTAO'!G:G) -> Cartão ativo
B11: JOELSON FERREIRA DOS SANTOS | C11: 07690263623 | D11: ANDREY | E11: REGIONAL MG | F11: CEF SUDESTE MG | G11: HUGO ALEXANDRE | H11: MARCOS CARIAS | I11: 0 | J11: 1023.33 | K11: 5000 | L11: 2159.92 | N11: =Tabela1[[#This Row],[1ª QZ]]-Tabela1[[#This Row],[SALDO FINAL]]-Tabela1[[#This Row],[SALDO CARTAO]]-Tabela1[[#This Row],[Adiantamento ]] -> 1816.75 | O11: =Tabela1[[#This Row],[SALDO REEMBOLSAR]]*$O$4 -> 0 | P11: =IF(Tabela1[[#This Row],[CARGA PARCIAL]]<0,0,Tabela1[[#This Row],[CARGA PARCIAL]])+Tabela1[[#This Row],[REEMBOLSO]] -> 1816.75 | Q11: 0 | R11: =Tabela1[[#This Row],[Carga CORRETA]]-Tabela1[[#This Row],[Carga RECEBIDA]] -> 1816.75 | S11: =_xlfn.XLOOKUP(Tabela1[[#This Row],[COLABORADOR]],'STATUS CARTAO'!D:D,'STATUS CARTAO'!G:G) -> Cartão ativo
B12: DANIEL DA SILVA LOPES | C12: 94288259053 | D12: STEFANI | E12: REGIONAL SC | F12: NET APOIO SC | G12: LEANDRO MARCUSSO | H12: EVERSON GAIDSTIECHI | I12: 0 | J12: 320.45 | K12: 2710 | L12: 0 | N12: =Tabela1[[#This Row],[1ª QZ]]-Tabela1[[#This Row],[SALDO FINAL]]-Tabela1[[#This Row],[SALDO CARTAO]]-Tabela1[[#This Row],[Adiantamento ]] -> 2389.55 | O12: =Tabela1[[#This Row],[SALDO REEMBOLSAR]]*$O$4 -> 0 | P12: =IF(Tabela1[[#This Row],[CARGA PARCIAL]]<0,0,Tabela1[[#This Row],[CARGA PARCIAL]])+Tabela1[[#This Row],[REEMBOLSO]] -> 2389.55 | Q12: 648 | R12: =Tabela1[[#This Row],[Carga CORRETA]]-Tabela1[[#This Row],[Carga RECEBIDA]] -> 1741.55 | S12: =_xlfn.XLOOKUP(Tabela1[[#This Row],[COLABORADOR]],'STATUS CARTAO'!D:D,'STATUS CARTAO'!G:G) -> Cartão ativo
B13: PAULO NILTON COSTA MOREIRA | C13: 45159599053 | D13: ANDREY | E13: REGIONAL RS | F13: CEF EXTREMO SUL RS | G13: ALEXANDRE GROSS | H13: EVERSON GAIDSTIECHI | I13: 0 | J13: 166.28 | K13: 3000 | L13: 225.98 | N13: =Tabela1[[#This Row],[1ª QZ]]-Tabela1[[#This Row],[SALDO FINAL]]-Tabela1[[#This Row],[SALDO CARTAO]]-Tabela1[[#This Row],[Adiantamento ]] -> 2607.74 | O13: =Tabela1[[#This Row],[SALDO REEMBOLSAR]]*$O$4 -> 0 | P13: =IF(Tabela1[[#This Row],[CARGA PARCIAL]]<0,0,Tabela1[[#This Row],[CARGA PARCIAL]])+Tabela1[[#This Row],[REEMBOLSO]] -> 2607.74 | Q13: 1081.76 | R13: =Tabela1[[#This Row],[Carga CORRETA]]-Tabela1[[#This Row],[Carga RECEBIDA]] -> 1525.98 | S13: =_xlfn.XLOOKUP(Tabela1[[#This Row],[COLABORADOR]],'STATUS CARTAO'!D:D,'STATUS CARTAO'!G:G) -> Cartão ativo
B14: PATRICK ANTONIEVICZ ALVES | C14: 06456801923 | D14: STEFANI | E14: REGIONAL SC | F14: TRIBUNAL DE JUSTICA PR | G14: LEANDRO MARCUSSO | H14: EVERSON GAIDSTIECHI | I14: 0 | J14: 0 | K14: 1400 | L14: 0 | N14: =Tabela1[[#This Row],[1ª QZ]]-Tabela1[[#This Row],[SALDO FINAL]]-Tabela1[[#This Row],[SALDO CARTAO]]-Tabela1[[#This Row],[Adiantamento ]] -> 1400 | O14: =Tabela1[[#This Row],[SALDO REEMBOLSAR]]*$O$4 -> 0 | P14: =IF(Tabela1[[#This Row],[CARGA PARCIAL]]<0,0,Tabela1[[#This Row],[CARGA PARCIAL]])+Tabela1[[#This Row],[REEMBOLSO]] -> 1400 | Q14: 21 | R14: =Tabela1[[#This Row],[Carga CORRETA]]-Tabela1[[#This Row],[Carga RECEBIDA]] -> 1379 | S14: =_xlfn.XLOOKUP(Tabela1[[#This Row],[COLABORADOR]],'STATUS CARTAO'!D:D,'STATUS CARTAO'!G:G) -> Cartão ativo
B15: FRANCIELLY FELIX CAVALCANTE DE ANDRADE | C15: 09276240446 | D15: ANDREY | E15: REGIONAL CO | F15: CEF AM AC RR | G15: ANGELICA SOARES | H15: ROGERIO SCATAMBULO | I15: 0 | J15: 390.44 | K15: 4000 | L15: 0 | N15: =Tabela1[[#This Row],[1ª QZ]]-Tabela1[[#This Row],[SALDO FINAL]]-Tabela1[[#This Row],[SALDO CARTAO]]-Tabela1[[#This Row],[Adiantamento ]] -> 3609.56 | O15: =Tabela1[[#This Row],[SALDO REEMBOLSAR]]*$O$4 -> 0 | P15: =IF(Tabela1[[#This Row],[CARGA PARCIAL]]<0,0,Tabela1[[#This Row],[CARGA PARCIAL]])+Tabela1[[#This Row],[REEMBOLSO]] -> 3609.56 | Q15: 2609.56 | R15: =Tabela1[[#This Row],[Carga CORRETA]]-Tabela1[[#This Row],[Carga RECEBIDA]] -> 1000 | S15: =_xlfn.XLOOKUP(Tabela1[[#This Row],[COLABORADOR]],'STATUS CARTAO'!D:D,'STATUS CARTAO'!G:G) -> Cartão ativo
B16: LUCAS RODRIGUES DE MOURA GALVAO | C16: 04013986175 | D16: ANDREY | E16: REGIONAL CO | F16: CEF GOIANIA CO | G16: ANGELICA SOARES | H16: ROGERIO SCATAMBULO | I16: 0 | J16: 1995.77 | K16: 3000 | L16: 5.25 | N16: =Tabela1[[#This Row],[1ª QZ]]-Tabela1[[#This Row],[SALDO FINAL]]-Tabela1[[#This Row],[SALDO CARTAO]]-Tabela1[[#This Row],[Adiantamento ]] -> 998.98 | O16: =Tabela1[[#This Row],[SALDO REEMBOLSAR]]*$O$4 -> 0 | P16: =IF(Tabela1[[#This Row],[CARGA PARCIAL]]<0,0,Tabela1[[#This Row],[CARGA PARCIAL]])+Tabela1[[#This Row],[REEMBOLSO]] -> 998.98 | Q16: 0 | R16: =Tabela1[[#This Row],[Carga CORRETA]]-Tabela1[[#This Row],[Carga RECEBIDA]] -> 998.98 | S16: =_xlfn.XLOOKUP(Tabela1[[#This Row],[COLABORADOR]],'STATUS CARTAO'!D:D,'STATUS CARTAO'!G:G) -> Cartão ativo
B17: EDUARDO SANTOS | C17: 91270529072 | D17: ANDREY | E17: REGIONAL RS | F17: NET APOIO RS | G17: ALEXANDRE GROSS | H17: EVERSON GAIDSTIECHI | I17: 0 | J17: 0 | K17: 2500 | L17: 1106.25 | N17: =Tabela1[[#This Row],[1ª QZ]]-Tabela1[[#This Row],[SALDO FINAL]]-Tabela1[[#This Row],[SALDO CARTAO]]-Tabela1[[#This Row],[Adiantamento ]] -> 1393.75 | O17: =Tabela1[[#This Row],[SALDO REEMBOLSAR]]*$O$4 -> 0 | P17: =IF(Tabela1[[#This Row],[CARGA PARCIAL]]<0,0,Tabela1[[#This Row],[CARGA PARCIAL]])+Tabela1[[#This Row],[REEMBOLSO]] -> 1393.75 | Q17: 428.76 | R17: =Tabela1[[#This Row],[Carga CORRETA]]-Tabela1[[#This Row],[Carga RECEBIDA]] -> 964.99 | S17: =_xlfn.XLOOKUP(Tabela1[[#This Row],[COLABORADOR]],'STATUS CARTAO'!D:D,'STATUS CARTAO'!G:G) -> Cartão ativo
B18: FABIO PROVESI | C18: 05731312958 | D18: STEFANI | E18: REGIONAL SC | F18: BB SERET SC | G18: LEANDRO MARCUSSO | H18: EVERSON GAIDSTIECHI | I18: 0 | J18: 1432.79 | K18: 3500 | L18: 24.02 | N18: =Tabela1[[#This Row],[1ª QZ]]-Tabela1[[#This Row],[SALDO FINAL]]-Tabela1[[#This Row],[SALDO CARTAO]]-Tabela1[[#This Row],[Adiantamento ]] -> 2043.19 | O18: =Tabela1[[#This Row],[SALDO REEMBOLSAR]]*$O$4 -> 0 | P18: =IF(Tabela1[[#This Row],[CARGA PARCIAL]]<0,0,Tabela1[[#This Row],[CARGA PARCIAL]])+Tabela1[[#This Row],[REEMBOLSO]] -> 2043.19 | Q18: 1375.17 | R18: =Tabela1[[#This Row],[Carga CORRETA]]-Tabela1[[#This Row],[Carga RECEBIDA]] -> 668.02 | S18: =_xlfn.XLOOKUP(Tabela1[[#This Row],[COLABORADOR]],'STATUS CARTAO'!D:D,'STATUS CARTAO'!G:G) -> Cartão ativo
... B51: WELTON GERALDO WROBLEWSKI | C51: 91443130982 | D51: STEFANI | E51: REGIONAL SC | F51: TRIBUNAL DE JUSTICA PR | G51: LEANDRO MARCUSSO | H51: EVERSON GAIDSTIECHI | I51: 0 | J51: 9.4644292e-12 | K51: 800 | L51: 101.85 | N51: =Tabela1[[#This Row],[1ª QZ]]-Tabela1[[#This Row],[SALDO FINAL]]-Tabela1[[#This Row],[SALDO CARTAO]]-Tabela1[[#This Row],[Adiantamento ]] -> 698.15 | O51: =Tabela1[[#This Row],[SALDO REEMBOLSAR]]*$O$4 -> 0 | P51: =IF(Tabela1[[#This Row],[CARGA PARCIAL]]<0,0,Tabela1[[#This Row],[CARGA PARCIAL]])+Tabela1[[#This Row],[REEMBOLSO]] -> 698.15 | Q51: 596.3 | R51: =Tabela1[[#This Row],[Carga CORRETA]]-Tabela1[[#This Row],[Carga RECEBIDA]] -> 101.85 | S51: =_xlfn.XLOOKUP(Tabela1[[#This Row],[COLABORADOR]],'STATUS CARTAO'!D:D,'STATUS CARTAO'!G:G) -> Cartão ativo

Sheet RETIRAR
B2: COLABORADOR | C2: CPF | D2: SITUAÇÃO | E2: REGIONAL | F2: CENTRO DE CUSTO | G2: GESTOR | H2: DIRETOR | I2: SALDO REEMBOLSAR | J2: REEMBOLSO FEITO | K2: REEMBOLSO CORRETO | L2: RETIRAR
B3: CARLOS RENATO PACHECO DA SILVA | C3: 90443306087 | D3: ATIVO | E3: REGIONAL RS | F3: CEF LESTE GAUCHO RS | G3: ALEXANDRE GROSS | H3: EVERSON GAIDSTIECHI | I3: 2222.63 | J3: 1333.578 | K3: 1111.315 | L3: 222.263
B4: SANDRO BARRETO DE SOUZA | C4: 78021324953 | D4: ATIVO | E4: REGIONAL SC | F4: CEF SUL SC | G4: LEANDRO MARCUSSO | H4: EVERSON GAIDSTIECHI | I4: 2038.88 | J4: 1223.328 | K4: 1019.44 | L4: 203.888
B5: CLAUDEMIR GREGOSKI RODRIGUES | C5: 05144026958 | D5: ATIVO | E5: REGIONAL SC | F5: CEF FACILITIES CURITIBA PR | G5: LEANDRO MARCUSSO | H5: EVERSON GAIDSTIECHI | I5: 1900 | J5: 1140 | K5: 950 | L5: 190
B6: LEANDRO GUSMAO MUNIZ | C6: 13126691790 | D6: ATIVO | E6: REGIONAL RJ | F6: CEF INTERIOR RJ | G6: ALLAN JEFFERSON | H6: ROGERIO SCATAMBULO | I6: 1545 | J6: 927 | K6: 772.5 | L6: 154.5
B7: MARCELO GIMENEZ ARGEMON | C7: 95073272153 | D7: ATIVO | E7: REGIONAL SP | F7: CEF FACILITIES CAMPINAS SP | G7: LEANDRO NUNES | H7: EVERSON GAIDSTIECHI | I7: 1256 | J7: 753.6 | K7: 628 | L7: 125.6
B8: MARIA EDUARDA ARAGAO | C8: 10363402950 | D8: ATIVO | E8: REGIONAL SC | F8: CEF SUL SC | G8: LEANDRO MARCUSSO | H8: EVERSON GAIDSTIECHI | I8: 960.45 | J8: 576.27 | K8: 480.225 | L8: 96.045
B9: GUILHERME MOTTA RIBEIRO SILVA | C9: 11178519740 | D9: ATIVO | E9: REGIONAL ES | F9: CEF ES | G9: VINICIUS LOCATELLY | H9: MARCOS CARIAS | I9: 921.06 | J9: 552.636 | K9: 460.53 | L9: 92.106
B10: JUNIO VICENTE BARBOSA | C10: 10054353670 | D10: ATIVO | E10: REGIONAL MG | F10: CEF NORDESTE MG | G10: HUGO ALEXANDRE | H10: MARCOS CARIAS | I10: 848.61 | J10: 509.166 | K10: 424.305 | L10: 84.861
B11: TEOFILO TOLLENDAL PACHECO | C11: 26687333836 | D11: ATIVO | E11: REGIONAL SP | F11: TELEFONICA SP | G11: LEANDRO NUNES | H11: EVERSON GAIDSTIECHI | I11: 818.79 | J11: 491.274 | K11: 409.395 | L11: 81.879
B12: MARCELO DE ANDRADE CALVETTI | C12: 02587708052 | D12: ATIVO | E12: REGIONAL RS | F12: NET PORTO ALEGRE RS | G12: ALEXANDRE GROSS | H12: EVERSON GAIDSTIECHI | I12: 807.82 | J12: 484.692 | K12: 403.91 | L12: 80.782
B13: LEANDRO MARCUSSO | C13: 01857561902 | D13: ATIVO | E13: REGIONAL SC | F13: ADM FILIAL SC | G13: LEANDRO MARCUSSO | H13: EVERSON GAIDSTIECHI | I13: 806.09 | J13: 483.654 | K13: 403.045 | L13: 80.609
B14: JOSE JONAS FURLANETTO | C14: 55889913115 | D14: ATIVO | E14: REGIONAL SC | F14: BB NORTE OESTE PR | G14: LEANDRO MARCUSSO | H14: EVERSON GAIDSTIECHI | I14: 803.22 | J14: 481.932 | K14: 401.61 | L14: 80.322
... B59: ISAIAS DA SILVA | C59: 04083479965 | D59: ATIVO | E59: REGIONAL SC | F59: TRIBUNAL DE JUSTICA PR | G59: LEANDRO MARCUSSO | H59: EVERSON GAIDSTIECHI | I59: 10.02 | J59: 6.012 | K59: 5.01 | L59: 1.002

Sheet STATUS CARTAO
C2: Cobrança | D2: Nome | E2: E-mail | F2: Tipo de usuário | G2: Status do Cartão | H2: Permissão de Uso | I2: Permissão de Gestão | J2: Ações
D3: ABNER ANDRADE CAVALCANTE | E3: abner.cavalcante@eqsengenharia.com.br | F3: Normal | G3: Cartão ativo | H3: Portador de Cartão | I3: Sem permissão
D4: ADAN LEONARDO SOUZA BATISTA | E4: adan.batista@eqsengenharia.com.br | F4: Normal | G4: Cartão ativo | H4: Portador de Cartão | I4: Sem permissão
D5: ADAUTO JOSE PEREIRA | E5: adautojosepereira@yahoo.com.br | F5: Normal | G5: Cartão ativo | H5: Portador de Cartão | I5: Sem permissão
D6: ADEMARCIO DUARTE LOPES | E6: ctba_projetos@hotmail.com | F6: Normal | G6: Cartão ativo | H6: Portador de Cartão | I6: Sem permissão
D7: ADILSON ANTONIO JACINTO | E7: dirson4867@yahoo.com | F7: Normal | G7: Cartão ativo | H7: Portador de Cartão | I7: Sem permissão
D8: ADILSON MELLO DE CAMARGO | E8: adilsoncamargo@eqseng.com.br | F8: Normal | G8: Cartão ativo | H8: Portador de Cartão | I8: Sem permissão
D9: ADILSON RODRIGUES FERREIRA | E9: adilson.ferreira@eqsengenharia.com.br | F9: Intermediário | G9: Cadastro pendente | H9: Portador de Cartão | I9: Sem permissão
D10: ADIVAR ANTONIO DA SILVA JUNIOR | E10: adivarjunior@gmail.com | F10: Normal | G10: Cartão ativo | H10: Portador de Cartão | I10: Sem permissão
D11: ADMILSON DA SILVA FARIAS | E11: admilsonfarias2016@gmail.com | F11: Normal | G11: Cadastro pendente | H11: Portador de Cartão | I11: Sem permissão
D12: ADMILSON DOS SANTOS GALAN | E12: admilsongalan@gmail.com | F12: Normal | G12: Cartão ativo | H12: Portador de Cartão | I12: Sem permissão
D13: ADRIANA DA CONCEICAO PEREIRA DE MELO | E13: adriana.melo@eqsengenharia.com.br | F13: Normal | G13: Cadastro pendente | H13: Portador de Cartão | I13: Sem permissão
D14: ADRIANE CARON | E14: adriane.caron@eqseng.com.br | F14: Normal | G14: Cartão ativo | H14: Portador de Cartão | I14: Sem permissão
... D52: ANDRE ARANHA MEISTER | E52: andre.meister@eqsengenharia.com.br | F52: Normal | G52: Cartão ativo | H52: Portador de Cartão | I52: Sem permissão
C53: Cobrança | D53: Nome | E53: E-mail | F53: Tipo de usuário | G53: Status do Cartão | H53: Permissão de Uso | I53: Permissão de Gestão | J53: Ações
D54: ANDRE DE MOURA ESCOBAR | E54: andre.escobar@eqseng.com.br | F54: Normal | G54: Cartão ativo | H54: Portador de Cartão | I54: Sem permissão
D55: ANDRE LUIZ DOS SANTOS OLIVEIRA | E55: andre.oliveira.supervisor.telecom@gmail.com | F55: Normal | G55: Cadastro pendente | H55: Portador de Cartão | I55: Sem permissão
D56: ANDRE LUIZ SANTANA | E56: andre.santana@eqsengenharia.com.br | F56: Normal | G56: Cartão ativo | H56: Portador de Cartão | I56: Sem permissão
D57: ANDRE PINHEIRO BALOTIN | E57: andre.balotin@eqsengenharia.com.br | F57: Normal | G57: Cartão ativo | H57: Portador de Cartão | I57: Sem permissão
D58: ANDRE VALERIO DE PAIVA | E58: toxcroen@gmail.com | F58: Normal | G58: Cartão ativo | H58: Portador de Cartão | I58: Sem permissão
D59: ANDREA ANTUNES GOMES | E59: andrea.antunes@eqsengenharia.com.br | F59: Normal | G59: Cartão ativo | H59: Portador de Cartão | I59: Sem permissão
D60: ANDRESA INDIRA SANTANA AGGIO | E60: andresa.aggio@eqsengenharia.com.br | F60: Normal | G60: Cartão ativo | H60: Portador de Cartão | I60: Sem permissão
D61: ANDREY CARDOSO REGINALDO | E61: andrey.reginaldo@eqsengenharia.com.br | F61: Administrador | G61: Cadastro pendente | H61: Portador de Cartão | I61: Gestor de Contas
D62: ANELISE MENDONCA DE AVILA | E62: anelise@eqsengenharia.com.br | F62: Normal | G62: Cartão ativo | H62: Portador de Cartão | I62: Sem permissão
D63: Angelica Sampaio Sousa | E63: angelica.sousa@eqsengenharia.com.br | F63: Normal | G63: Cartão ativo | H63: Portador de Cartão | I63: Sem permissão
D64: ANGELICA SOARES AMARANTE SILVA | E64: angelica.amarante@eqsengenharia.com.br | F64: Intermediário | G64: Cartão ativo | H64: Portador de Cartão | I64: Sem permissão
D65: ANTONIO DE PADUA LEITE | E65: antonio@eqseng.com.br | F65: Normal | G65: Cartão ativo | H65: Portador de Cartão | I65: Sem permissão
... D103: CHARLES NEVES MATTIUZZI | E103: cmattyuzzy@gmail.com | F103: Normal | G103: Cartão ativo | H103: Portador de Cartão | I103: Sem permissão
C104: Cobrança | D104: Nome | E104: E-mail | F104: Tipo de usuário | G104: Status do Cartão | H104: Permissão de Uso | I104: Permissão de Gestão | J104: Ações
D105: CHARLYTON COSTA ANDRADE | E105: charlyton.andrade@eqsengenharia.com.br | F105: Normal | G105: Cartão ativo | H105: Portador de Cartão | I105: Sem permissão
D106: CINTIA DOS SANTOS RABELO | E106: cintia.rabelo@eqsengenharia.com.br | F106: Normal | G106: Cartão ativo | H106: Portador de Cartão | I106: Sem permissão
D107: CLAUDEMIR GREGOSKI RODRIGUES | E107: claudemir.rodrigues@eqsengenharia.com.br | F107: Normal | G107: Cartão ativo | H107: Portador de Cartão | I107: Sem permissão
D108: CLAUDEMIR MOREIRA | E108: claudemir.moreura054@gmail.com | F108: Normal | G108: Cartão ativo | H108: Portador de Cartão | I108: Sem permissão
D109: CLAUDINEI AMARAL | E109: amaralclaudinei@hotmail.com | F109: Normal | G109: Cartão ativo | H109: Portador de Cartão | I109: Sem permissão
D110: CLAUDINEI VICENTE DE LIMA | E110: claudinei.lima@eqsengenharia.com.br | F110: Normal | G110: Cartão ativo | H110: Portador de Cartão | I110: Sem permissão
D111: CLAUDIO DONIZETE DA SILVA | E111: claudiodonizete8321@gmail.com | F111: Normal | G111: Cartão ativo | H111: Portador de Cartão | I111: Sem permissão
D112: CLAUDIO RENALDI NUNES | E112: clrenaldinunes@gmail.com | F112: Normal | G112: Cartão ativo | H112: Portador de Cartão | I112: Sem permissão
D113: CLAYTON DE OLIVEIRA | E113: claytonpr@gmail.com | F113: Normal | G113: Cartão ativo | H113: Portador de Cartão | I113: Sem permissão
D114: CLEBERSON APARECIDO BORGES DOS SANTOS | E114: binhoclebersonsantos@gmail.com | F114: Normal | G114: Cartão ativo | H114: Portador de Cartão | I114: Sem permissão
D115: CLEDIVALDO DINIZ BERNARDO | E115: DINIZCLEDIVALDO@GMAIL.COM | F115: Normal | G115: Cartão não habilitado | H115: Sem permissão | I115: Sem permissão
...
