Workbook

Sheet 1 QZ JUNHO
N4: 0.6
H5: =SUBTOTAL(9,H7:H343) -> 0 | I5: =SUBTOTAL(9,I7:I343) -> 9122.95 | J5: =SUBTOTAL(9,J7:J343) -> 1500 | K5: =SUBTOTAL(9,K7:K343) -> 17.1 | L5: =SUBTOTAL(9,L7:L343) -> 0 | M5: =SUBTOTAL(9,M7:M343) -> -7640.05 | N5: =SUBTOTAL(9,N7:N343) -> 0 | O5: =SUBTOTAL(9,O7:O393) -> 0
A6: COLABORADOR | B6: CPF | C6: SITUAÇÃO | D6: REGIONAL | E6: CENTRO DE CUSTO | F6: GESTOR | G6: DIRETOR | H6: SALDO REEMBOLSAR | I6: SALDO FINAL | J6: 1ª QZ | K6: SALDO CARTAO | L6: Adiantamento | M6: CARGA PARCIAL | N6: REEMBOLSO | O6: Carga Final | P6: obs | Q6: STATUS DO CARTÃO
A7: ABNER ANDRADE CAVALCANTE | B7: 02027745203 | C7: ATIVO | D7: REGIONAL CO | E7: CEF AM AC RR | F7: ANGELICA SOARES | G7: ROGERIO SCATAMBULO | H7: 227.55 | I7: 0 | J7: 9840 | K7: 5 | M7: =Tabela1[[#This Row],[1ª QZ]]-Tabela1[[#This Row],[SALDO FINAL]]-Tabela1[[#This Row],[SALDO CARTAO]]-Tabela1[[#This Row],[Adiantamento ]] -> 9835 | N7: =Tabela1[[#This Row],[SALDO REEMBOLSAR]]*$N$4 -> 136.53 | O7: 9948.775 | Q7: =_xlfn.XLOOKUP(Tabela1[[#This Row],[COLABORADOR]],'STATUS CARTAO'!D:D,'STATUS CARTAO'!G:G) -> Cartão ativo
A8: ADAN LEONARDO SOUZA BATISTA | B8: 01932662537 | C8: ATIVO | D8: REGIONAL NE | E8: TELEFONICA BA | F8: GERSON OLIVEIRA | G8: ROGERIO SCATAMBULO | H8: 0 | I8: 601.41 | J8: 1000 | K8: 3 | M8: =Tabela1[[#This Row],[1ª QZ]]-Tabela1[[#This Row],[SALDO FINAL]]-Tabela1[[#This Row],[SALDO CARTAO]]-Tabela1[[#This Row],[Adiantamento ]] -> 395.59 | N8: =Tabela1[[#This Row],[SALDO REEMBOLSAR]]*$N$4 -> 0 | O8: 395.59 | Q8: =_xlfn.XLOOKUP(Tabela1[[#This Row],[COLABORADOR]],'STATUS CARTAO'!D:D,'STATUS CARTAO'!G:G) -> Cartão ativo
A9: ADAUTO JOSE PEREIRA | B9: 85087572634 | C9: ATIVO | D9: REGIONAL MG | E9: CEF FACILITIES BH | F9: HUGO ALEXANDRE | G9: MARCOS CARIAS | H9: 0 | I9: 116.83 | J9: 500 | K9: 1.1 | M9: =Tabela1[[#This Row],[1ª QZ]]-Tabela1[[#This Row],[SALDO FINAL]]-Tabela1[[#This Row],[SALDO CARTAO]]-Tabela1[[#This Row],[Adiantamento ]] -> 382.07 | N9: =Tabela1[[#This Row],[SALDO REEMBOLSAR]]*$N$4 -> 0 | O9: 382.07 | Q9: =_xlfn.XLOOKUP(Tabela1[[#This Row],[COLABORADOR]],'STATUS CARTAO'!D:D,'STATUS CARTAO'!G:G) -> Cartão ativo
A10: ADEMARCIO DUARTE LOPES | B10: 06223031980 | C10: ATIVO | D10: REGIONAL SC | E10: CEF FACILITIES CURITIBA PR | F10: LEANDRO MARCUSSO | G10: EVERSON GAIDSTIECHI | H10: 0 | I10: 1963.08 | J10: 2000 | K10: 2567.13 | M10: =Tabela1[[#This Row],[1ª QZ]]-Tabela1[[#This Row],[SALDO FINAL]]-Tabela1[[#This Row],[SALDO CARTAO]]-Tabela1[[#This Row],[Adiantamento ]] -> -2530.21 | N10: =Tabela1[[#This Row],[SALDO REEMBOLSAR]]*$N$4 -> 0 | O10: 0 | Q10: =_xlfn.XLOOKUP(Tabela1[[#This Row],[COLABORADOR]],'STATUS CARTAO'!D:D,'STATUS CARTAO'!G:G) -> Cartão ativo
A11: ADILSON MELLO DE CAMARGO | B11: 67324398049 | C11: ATIVO | D11: REGIONAL RS | E11: BB SERET RS | F11: ALEXANDRE GROSS | G11: EVERSON GAIDSTIECHI | H11: 0 | I11: 759.37 | J11: 800 | K11: 43 | M11: =Tabela1[[#This Row],[1ª QZ]]-Tabela1[[#This Row],[SALDO FINAL]]-Tabela1[[#This Row],[SALDO CARTAO]]-Tabela1[[#This Row],[Adiantamento ]] -> -2.37 | N11: =Tabela1[[#This Row],[SALDO REEMBOLSAR]]*$N$4 -> 0 | O11: 0 | Q11: =_xlfn.XLOOKUP(Tabela1[[#This Row],[COLABORADOR]],'STATUS CARTAO'!D:D,'STATUS CARTAO'!G:G) -> Cartão ativo
A12: ADIVAR ANTONIO DA SILVA JUNIOR | B12: 28604876898 | C12: ATIVO | D12: REGIONAL CLARO INFRA SUL | E12: CLARO INFRA SC | F12: BRUNO EDUARDO | G12: EVERSON GAIDSTIECHI | H12: 0 | I12: 342.63 | J12: 160 | K12: 48.2 | M12: =Tabela1[[#This Row],[1ª QZ]]-Tabela1[[#This Row],[SALDO FINAL]]-Tabela1[[#This Row],[SALDO CARTAO]]-Tabela1[[#This Row],[Adiantamento ]] -> -230.83 | N12: =Tabela1[[#This Row],[SALDO REEMBOLSAR]]*$N$4 -> 0 | O12: 0 | Q12: =_xlfn.XLOOKUP(Tabela1[[#This Row],[COLABORADOR]],'STATUS CARTAO'!D:D,'STATUS CARTAO'!G:G) -> Cartão ativo
A13: ADMILSON DOS SANTOS GALAN | B13: 04769973993 | C13: ATIVO | D13: REGIONAL SC | E13: CEF NORTE SC | F13: LEANDRO MARCUSSO | G13: EVERSON GAIDSTIECHI | H13: 0 | I13: 617.35 | J13: 1680 | K13: 8.58 | M13: =Tabela1[[#This Row],[1ª QZ]]-Tabela1[[#This Row],[SALDO FINAL]]-Tabela1[[#This Row],[SALDO CARTAO]]-Tabela1[[#This Row],[Adiantamento ]] -> 1054.07 | N13: =Tabela1[[#This Row],[SALDO REEMBOLSAR]]*$N$4 -> 0 | O13: 1054.07 | Q13: =_xlfn.XLOOKUP(Tabela1[[#This Row],[COLABORADOR]],'STATUS CARTAO'!D:D,'STATUS CARTAO'!G:G) -> Cartão ativo
A14: ADRIANO FRANCISCO DE PAULA | B14: 08813588607 | C14: ATIVO | D14: REGIONAL MG | E14: CLARO INFRA MG | F14: HUGO ALEXANDRE | G14: MARCOS CARIAS | H14: 0 | I14: 480.58 | J14: 400 | K14: 90.58 | M14: =Tabela1[[#This Row],[1ª QZ]]-Tabela1[[#This Row],[SALDO FINAL]]-Tabela1[[#This Row],[SALDO CARTAO]]-Tabela1[[#This Row],[Adiantamento ]] -> -171.16 | N14: =Tabela1[[#This Row],[SALDO REEMBOLSAR]]*$N$4 -> 0 | O14: 0 | Q14: =_xlfn.XLOOKUP(Tabela1[[#This Row],[COLABORADOR]],'STATUS CARTAO'!D:D,'STATUS CARTAO'!G:G) -> Cartão ativo
A15: ADSON ARAUJO DA SILVA | B15: 94551804304 | C15: ATIVO | D15: REGIONAL CLARO INFRA NORDESTE | E15: CLARO INFRA NORDESTE | F15: FELIPE JOSE | G15: ROGERIO SCATAMBULO | H15: 796.12 | I15: 0 | J15: 1600 | K15: 6 | M15: =Tabela1[[#This Row],[1ª QZ]]-Tabela1[[#This Row],[SALDO FINAL]]-Tabela1[[#This Row],[SALDO CARTAO]]-Tabela1[[#This Row],[Adiantamento ]] -> 1594 | N15: =Tabela1[[#This Row],[SALDO REEMBOLSAR]]*$N$4 -> 477.672 | O15: 1992.06 | Q15: =_xlfn.XLOOKUP(Tabela1[[#This Row],[COLABORADOR]],'STATUS CARTAO'!D:D,'STATUS CARTAO'!G:G) -> Cartão ativo
A16: ADSON SANTOS DA SILVA | B16: 83058133553 | C16: ATIVO | D16: REGIONAL NE | E16: TELEFONICA BA | F16: GERSON OLIVEIRA | G16: ROGERIO SCATAMBULO | H16: 0 | I16: 1978 | J16: 2000 | K16: 5.51 | M16: =Tabela1[[#This Row],[1ª QZ]]-Tabela1[[#This Row],[SALDO FINAL]]-Tabela1[[#This Row],[SALDO CARTAO]]-Tabela1[[#This Row],[Adiantamento ]] -> 16.49 | N16: =Tabela1[[#This Row],[SALDO REEMBOLSAR]]*$N$4 -> 0 | O16: 16.49 | Q16: =_xlfn.XLOOKUP(Tabela1[[#This Row],[COLABORADOR]],'STATUS CARTAO'!D:D,'STATUS CARTAO'!G:G) -> Cartão ativo
A17: AGNO CHRISTIAN DE LIMA TELES | B17: 06911519624 | C17: ATIVO | D17: REGIONAL MG | E17: CLARO INFRA MG | F17: HUGO ALEXANDRE | G17: MARCOS CARIAS | H17: 686.33 | I17: 0 | J17: 1000 | K17: 6.5 | M17: =Tabela1[[#This Row],[1ª QZ]]-Tabela1[[#This Row],[SALDO FINAL]]-Tabela1[[#This Row],[SALDO CARTAO]]-Tabela1[[#This Row],[Adiantamento ]] -> 993.5 | N17: =Tabela1[[#This Row],[SALDO REEMBOLSAR]]*$N$4 -> 411.798 | O17: 1336.665 | Q17: =_xlfn.XLOOKUP(Tabela1[[#This Row],[COLABORADOR]],'STATUS CARTAO'!D:D,'STATUS CARTAO'!G:G) -> Cartão ativo
A18: ALAERTE JACINTO JUNIOR | B18: 03071605994 | C18: ATIVO | D18: REGIONAL SC | E18: PTB AREAS VERDES SC | F18: LEANDRO MARCUSSO | G18: EVERSON GAIDSTIECHI | H18: 0 | I18: 351.32 | J18: 350 | K18: 31.32 | M18: =Tabela1[[#This Row],[1ª QZ]]-Tabela1[[#This Row],[SALDO FINAL]]-Tabela1[[#This Row],[SALDO CARTAO]]-Tabela1[[#This Row],[Adiantamento ]] -> -32.64 | N18: =Tabela1[[#This Row],[SALDO REEMBOLSAR]]*$N$4 -> 0 | O18: 0 | Q18: =_xlfn.XLOOKUP(Tabela1[[#This Row],[COLABORADOR]],'STATUS CARTAO'!D:D,'STATUS CARTAO'!G:G) -> Cartão ativo
... A31: ANDERSON RICARDO VIEIRA | B31: 07822591975 | C31: ATIVO | D31: REGIONAL SC | E31: BB NORTE OESTE PR | F31: LEANDRO MARCUSSO | G31: EVERSON GAIDSTIECHI | H31: 0 | I31: 0 | J31: 500 | K31: 0 | M31: =Tabela1[[#This Row],[1ª QZ]]-Tabela1[[#This Row],[SALDO FINAL]]-Tabela1[[#This Row],[SALDO CARTAO]]-Tabela1[[#This Row],[Adiantamento ]] -> 500 | N31: =Tabela1[[#This Row],[SALDO REEMBOLSAR]]*$N$4 -> 0 | O31: 500 | Q31: =_xlfn.XLOOKUP(Tabela1[[#This Row],[COLABORADOR]],'STATUS CARTAO'!D:D,'STATUS CARTAO'!G:G) -> Cartão ativo
A32: ANDRE ARANHA MEISTER | B32: 03032275326 | C32: ATIVO | D32: REGIONAL CO | E32: BB MARANHAO MA | F32: ANGELICA SOARES | G32: ROGERIO SCATAMBULO | H32: 0 | I32: 35614.06 | J32: 9000 | K32: 4.57 | L32: 4000 | M32: =Tabela1[[#This Row],[1ª QZ]]-Tabela1[[#This Row],[SALDO FINAL]]-Tabela1[[#This Row],[SALDO CARTAO]]-Tabela1[[#This Row],[Adiantamento ]] -> -30618.63 | N32: =Tabela1[[#This Row],[SALDO REEMBOLSAR]]*$N$4 -> 0 | O32: 0 | Q32: =_xlfn.XLOOKUP(Tabela1[[#This Row],[COLABORADOR]],'STATUS CARTAO'!D:D,'STATUS CARTAO'!G:G) -> Cartão ativo
A33: ANDRE LUIZ SANTANA | B33: 11897381638 | C33: ATIVO | D33: REGIONAL RS | E33: CEF SERRA GAUCHA RS | F33: ALEXANDRE GROSS | G33: EVERSON GAIDSTIECHI | H33: 0 | I33: 0 | J33: 2800 | K33: 1.75 | M33: =Tabela1[[#This Row],[1ª QZ]]-Tabela1[[#This Row],[SALDO FINAL]]-Tabela1[[#This Row],[SALDO CARTAO]]-Tabela1[[#This Row],[Adiantamento ]] -> 2798.25 | N33: =Tabela1[[#This Row],[SALDO REEMBOLSAR]]*$N$4 -> 0 | O33: 2798.25 | Q33: =_xlfn.XLOOKUP(Tabela1[[#This Row],[COLABORADOR]],'STATUS CARTAO'!D:D,'STATUS CARTAO'!G:G) -> Cartão ativo
A34: ANDRE PINHEIRO BALOTIN | B34: 98603566020 | C34: ATIVO | D34: REGIONAL CLARO INFRA SUL | E34: CELESC NORTE SC | F34: BRUNO EDUARDO | G34: EVERSON GAIDSTIECHI | H34: 0 | I34: 2450.98 | J34: 1200 | K34: 1708.41 | M34: =Tabela1[[#This Row],[1ª QZ]]-Tabela1[[#This Row],[SALDO FINAL]]-Tabela1[[#This Row],[SALDO CARTAO]]-Tabela1[[#This Row],[Adiantamento ]] -> -2959.39 | N34: =Tabela1[[#This Row],[SALDO REEMBOLSAR]]*$N$4 -> 0 | O34: 0 | Q34: =_xlfn.XLOOKUP(Tabela1[[#This Row],[COLABORADOR]],'STATUS CARTAO'!D:D,'STATUS CARTAO'!G:G) -> Cartão ativo
A35: ANDRE VALERIO DE PAIVA | B35: 12682517633 | C35: ATIVO | D35: REGIONAL MG | E35: CLARO INFRA MG | F35: HUGO ALEXANDRE | G35: MARCOS CARIAS | H35: 0 | I35: 1012.22 | J35: 400 | K35: 4.12 | M35: =Tabela1[[#This Row],[1ª QZ]]-Tabela1[[#This Row],[SALDO FINAL]]-Tabela1[[#This Row],[SALDO CARTAO]]-Tabela1[[#This Row],[Adiantamento ]] -> -616.34 | N35: =Tabela1[[#This Row],[SALDO REEMBOLSAR]]*$N$4 -> 0 | O35: 0 | Q35: =_xlfn.XLOOKUP(Tabela1[[#This Row],[COLABORADOR]],'STATUS CARTAO'!D:D,'STATUS CARTAO'!G:G) -> Cartão ativo
A36: ANDRESA INDIRA SANTANA AGGIO | B36: 33162718805 | C36: ATIVO | D36: REGIONAL SC | E36: ADM FILIAL SC | F36: LEANDRO MARCUSSO | G36: EVERSON GAIDSTIECHI | H36: 0 | I36: 1506.3 | J36: 1000 | K36: 969.8 | L36: 341.7 | M36: =Tabela1[[#This Row],[1ª QZ]]-Tabela1[[#This Row],[SALDO FINAL]]-Tabela1[[#This Row],[SALDO CARTAO]]-Tabela1[[#This Row],[Adiantamento ]] -> -1817.8 | N36: =Tabela1[[#This Row],[SALDO REEMBOLSAR]]*$N$4 -> 0 | O36: 0 | Q36: =_xlfn.XLOOKUP(Tabela1[[#This Row],[COLABORADOR]],'STATUS CARTAO'!D:D,'STATUS CARTAO'!G:G) -> Cartão ativo
A37: ANGELICA SOARES AMARANTE SILVA | B37: 07643300712 | C37: ATIVO | D37: REGIONAL CO | E37: ADM FILIAL CO | F37: ANGELICA SOARES | G37: ROGERIO SCATAMBULO | H37: 0 | I37: 9122.95 | J37: 1500 | K37: 17.1 | L37: 0 | M37: =Tabela1[[#This Row],[1ª QZ]]-Tabela1[[#This Row],[SALDO FINAL]]-Tabela1[[#This Row],[SALDO CARTAO]]-Tabela1[[#This Row],[Adiantamento ]] -> -7640.05 | N37: =Tabela1[[#This Row],[SALDO REEMBOLSAR]]*$N$4 -> 0 | O37: 0 | Q37: =_xlfn.XLOOKUP(Tabela1[[#This Row],[COLABORADOR]],'STATUS CARTAO'!D:D,'STATUS CARTAO'!G:G) -> Cartão ativo
A38: ANTONIO DE PADUA LEITE | B38: 26992280600 | C38: ATIVO | D38: REGIONAL MG | E38: VTAL CYBER MG | F38: HUGO ALEXANDRE | G38: MARCOS CARIAS | H38: 0 | I38: 367.33 | J38: 300 | K38: 4.82 | M38: =Tabela1[[#This Row],[1ª QZ]]-Tabela1[[#This Row],[SALDO FINAL]]-Tabela1[[#This Row],[SALDO CARTAO]]-Tabela1[[#This Row],[Adiantamento ]] -> -72.15 | N38: =Tabela1[[#This Row],[SALDO REEMBOLSAR]]*$N$4 -> 0 | O38: 0 | Q38: =_xlfn.XLOOKUP(Tabela1[[#This Row],[COLABORADOR]],'STATUS CARTAO'!D:D,'STATUS CARTAO'!G:G) -> Cartão ativo
A39: ANTONIO FERREIRA DE MENDONCA NETO | B39: 05766838760 | C39: ATIVO | D39: REGIONAL RJ | E39: TRIBUNAL DE JUSTICA RJ | F39: ALLAN JEFFERSON | G39: ROGERIO SCATAMBULO | H39: 0 | I39: 4790.77 | J39: 5000 | K39: 2666 | M39: =Tabela1[[#This Row],[1ª QZ]]-Tabela1[[#This Row],[SALDO FINAL]]-Tabela1[[#This Row],[SALDO CARTAO]]-Tabela1[[#This Row],[Adiantamento ]] -> -2456.77 | N39: =Tabela1[[#This Row],[SALDO REEMBOLSAR]]*$N$4 -> 0 | O39: 0 | Q39: =_xlfn.XLOOKUP(Tabela1[[#This Row],[COLABORADOR]],'STATUS CARTAO'!D:D,'STATUS CARTAO'!G:G) -> Cartão ativo
A40: ANTONIO JOSE PEREIRA DA SILVA | B40: 08326260401 | C40: ATIVO | D40: REGIONAL NE | E40: TELEFONICA NE | F40: GERSON OLIVEIRA | G40: ROGERIO SCATAMBULO | H40: 788.5 | I40: 0 | J40: 1000 | K40: 3 | M40: =Tabela1[[#This Row],[1ª QZ]]-Tabela1[[#This Row],[SALDO FINAL]]-Tabela1[[#This Row],[SALDO CARTAO]]-Tabela1[[#This Row],[Adiantamento ]] -> 997 | N40: =Tabela1[[#This Row],[SALDO REEMBOLSAR]]*$N$4 -> 473.1 | O40: 1391.25 | Q40: =_xlfn.XLOOKUP(Tabela1[[#This Row],[COLABORADOR]],'STATUS CARTAO'!D:D,'STATUS CARTAO'!G:G) -> Cartão ativo
A41: ANTONIO MARCOS CAMARGO | B41: 04836584990 | C41: ATIVO | D41: REGIONAL SC | E41: TRIBUNAL DE JUSTICA PR | F41: LEANDRO MARCUSSO | G41: EVERSON GAIDSTIECHI | H41: 0 | I41: 68.46 | J41: 800 | K41: 89.41 | M41: =Tabela1[[#This Row],[1ª QZ]]-Tabela1[[#This Row],[SALDO FINAL]]-Tabela1[[#This Row],[SALDO CARTAO]]-Tabela1[[#This Row],[Adiantamento ]] -> 642.13 | N41: =Tabela1[[#This Row],[SALDO REEMBOLSAR]]*$N$4 -> 0 | O41: 642.13 | Q41: =_xlfn.XLOOKUP(Tabela1[[#This Row],[COLABORADOR]],'STATUS CARTAO'!D:D,'STATUS CARTAO'!G:G) -> Cartão ativo
A42: ARLEY HENRIQUE DE SOUZA LUZ | B42: 01170402232 | C42: ATIVO | D42: REGIONAL CO | E42: CEF GOIANIA CO | F42: ANGELICA SOARES | G42: ROGERIO SCATAMBULO | H42: 0 | I42: 1453.02 | J42: 2000 | K42: 36 | M42: =Tabela1[[#This Row],[1ª QZ]]-Tabela1[[#This Row],[SALDO FINAL]]-Tabela1[[#This Row],[SALDO CARTAO]]-Tabela1[[#This Row],[Adiantamento ]] -> 510.98 | N42: =Tabela1[[#This Row],[SALDO REEMBOLSAR]]*$N$4 -> 0 | O42: 510.98 | Q42: =_xlfn.XLOOKUP(Tabela1[[#This Row],[COLABORADOR]],'STATUS CARTAO'!D:D,'STATUS CARTAO'!G:G) -> Cartão ativo
A43: ARTHUR GOMES DE PAULO | B43: 12877857603 | C43: ATIVO | D43: REGIONAL MG | E43: CLARO INFRA MG | F43: HUGO ALEXANDRE | G43: MARCOS CARIAS | H43: 0 | I43: 854.02 | J43: 800 | K43: 110.64 | M43: =Tabela1[[#This Row],[1ª QZ]]-Tabela1[[#This Row],[SALDO FINAL]]-Tabela1[[#This Row],[SALDO CARTAO]]-Tabela1[[#This Row],[Adiantamento ]] -> -164.66 | N43: =Tabela1[[#This Row],[SALDO REEMBOLSAR]]*$N$4 -> 0 | O43: 0 | Q43: =_xlfn.XLOOKUP(Tabela1[[#This Row],[COLABORADOR]],'STATUS CARTAO'!D:D,'STATUS CARTAO'!G:G) -> Cartão ativo
A44: ARTHUR SANTOS DE OLIVEIRA | B44: 13921847621 | C44: ATIVO | D44: REGIONAL MG | E44: CLARO INFRA MG | F44: HUGO ALEXANDRE | G44: MARCOS CARIAS | H44: 0 | I44: 35.56 | J44: 700 | K44: 3 | M44: =Tabela1[[#This Row],[1ª QZ]]-Tabela1[[#This Row],[SALDO FINAL]]-Tabela1[[#This Row],[SALDO CARTAO]]-Tabela1[[#This Row],[Adiantamento ]] -> 661.44 | N44: =Tabela1[[#This Row],[SALDO REEMBOLSAR]]*$N$4 -> 0 | O44: 661.44 | Q44: =_xlfn.XLOOKUP(Tabela1[[#This Row],[COLABORADOR]],'STATUS CARTAO'!D:D,'STATUS CARTAO'!G:G) -> Cartão ativo
A45: ARTUR JACO PAGANI DE SOUZA | B45: 07105914971 | C45: ATIVO | D45: REGIONAL CLARO INFRA SUL | E45: CLARO INFRA SC | F45: BRUNO EDUARDO | G45: EVERSON GAIDSTIECHI | H45: 0 | I45: 932.38 | J45: 80 | K45: 0.3 | M45: =Tabela1[[#This Row],[1ª QZ]]-Tabela1[[#This Row],[SALDO FINAL]]-Tabela1[[#This Row],[SALDO CARTAO]]-Tabela1[[#This Row],[Adiantamento ]] -> -852.68 | N45: =Tabela1[[#This Row],[SALDO REEMBOLSAR]]*$N$4 -> 0 | O45: 0 | Q45: =_xlfn.XLOOKUP(Tabela1[[#This Row],[COLABORADOR]],'STATUS CARTAO'!D:D,'STATUS CARTAO'!G:G) -> Cartão ativo
A46: AURO MOREIRA PEDROSO | B46: 32060157900 | C46: ATIVO | D46: REGIONAL SC | E46: BB NORTE OESTE PR | F46: LEANDRO MARCUSSO | G46: EVERSON GAIDSTIECHI | H46: 368.83 | I46: 0 | J46: 700 | K46: 144.11 | M46: =Tabela1[[#This Row],[1ª QZ]]-Tabela1[[#This Row],[SALDO FINAL]]-Tabela1[[#This Row],[SALDO CARTAO]]-Tabela1[[#This Row],[Adiantamento ]] -> 555.89 | N46: =Tabela1[[#This Row],[SALDO REEMBOLSAR]]*$N$4 -> 221.298 | O46: 740.305 | Q46: =_xlfn.XLOOKUP(Tabela1[[#This Row],[COLABORADOR]],'STATUS CARTAO'!D:D,'STATUS CARTAO'!G:G) -> Cartão ativo
A47: BEATRIZ SILVA DE SIQUEIRA | B47: 35575473880 | C47: ATIVO | D47: REGIONAL SP | E47: CEF SP SUL | F47: LEANDRO NUNES | G47: EVERSON GAIDSTIECHI | H47: 0 | I47: 1798.93 | J47: 2200 | K47: 9.21 | M47: =Tabela1[[#This Row],[1ª QZ]]-Tabela1[[#This Row],[SALDO FINAL]]-Tabela1[[#This Row],[SALDO CARTAO]]-Tabela1[[#This Row],[Adiantamento ]] -> 391.86 | N47: =Tabela1[[#This Row],[SALDO REEMBOLSAR]]*$N$4 -> 0 | O47: 391.86 | Q47: =_xlfn.XLOOKUP(Tabela1[[#This Row],[COLABORADOR]],'STATUS CARTAO'!D:D,'STATUS CARTAO'!G:G) -> Cartão ativo
A48: BEN HUR MENDES OLIVEIRA | B48: 00046347054 | C48: ATIVO | D48: REGIONAL CLARO INFRA SUL | E48: CLARO INFRA SC | F48: BRUNO EDUARDO | G48: EVERSON GAIDSTIECHI | H48: 0 | I48: 662.75 | J48: 120 | K48: 0 | M48: =Tabela1[[#This Row],[1ª QZ]]-Tabela1[[#This Row],[SALDO FINAL]]-Tabela1[[#This Row],[SALDO CARTAO]]-Tabela1[[#This Row],[Adiantamento ]] -> -542.75 | N48: =Tabela1[[#This Row],[SALDO REEMBOLSAR]]*$N$4 -> 0 | O48: 0 | Q48: =_xlfn.XLOOKUP(Tabela1[[#This Row],[COLABORADOR]],'STATUS CARTAO'!D:D,'STATUS CARTAO'!G:G) -> Cartão ativo
A49: BRUNA LAIS AZEVEDO CUNHA | B49: 07747008406 | C49: ATIVO | D49: REGIONAL CLARO INFRA NORDESTE | E49: CLARO INFRA NORDESTE | F49: FELIPE JOSE | G49: ROGERIO SCATAMBULO | H49: 138.11 | I49: 0 | J49: 1000 | K49: 56.66 | M49: =Tabela1[[#This Row],[1ª QZ]]-Tabela1[[#This Row],[SALDO FINAL]]-Tabela1[[#This Row],[SALDO CARTAO]]-Tabela1[[#This Row],[Adiantamento ]] -> 943.34 | N49: =Tabela1[[#This Row],[SALDO REEMBOLSAR]]*$N$4 -> 82.866 | O49: 1012.395 | Q49: =_xlfn.XLOOKUP(Tabela1[[#This Row],[COLABORADOR]],'STATUS CARTAO'!D:D,'STATUS CARTAO'!G:G) -> Cartão ativo
A50: BRUNA LAIS DOS SANTOS PESSOA | B50: 13459423625 | C50: ATIVO | D50: REGIONAL MG | E50: ASSEMBLEIA LEGISLATIVA MG | F50: HUGO ALEXANDRE | G50: MARCOS CARIAS | H50: 0 | I50: 661.88 | J50: 800 | K50: 327.29 | M50: =Tabela1[[#This Row],[1ª QZ]]-Tabela1[[#This Row],[SALDO FINAL]]-Tabela1[[#This Row],[SALDO CARTAO]]-Tabela1[[#This Row],[Adiantamento ]] -> -189.17 | N50: =Tabela1[[#This Row],[SALDO REEMBOLSAR]]*$N$4 -> 0 | O50: 0 | Q50: =_xlfn.XLOOKUP(Tabela1[[#This Row],[COLABORADOR]],'STATUS CARTAO'!D:D,'STATUS CARTAO'!G:G) -> Cartão ativo
A51: BRUNA LAIS DOS SANTOS PESSOA | B51: 13459423625 | D51: REGIONAL MG | E51: ASSEMBLEIA LEGISLATIVA MG | M51: =Tabela1[[#This Row],[1ª QZ]]-Tabela1[[#This Row],[SALDO FINAL]]-Tabela1[[#This Row],[SALDO CARTAO]]-Tabela1[[#This Row],[Adiantamento ]] -> 0 | N51: =Tabela1[[#This Row],[SALDO REEMBOLSAR]]*$N$4 -> 0 | O51: 288.12 | Q51: =_xlfn.XLOOKUP(Tabela1[[#This Row],[COLABORADOR]],'STATUS CARTAO'!D:D,'STATUS CARTAO'!G:G) -> Cartão ativo
A52: BRUNO EDUARDO DE SOUZA | B52: 82341478972 | C52: ATIVO | D52: REGIONAL SC | E52: CLARO INFRA SC | F52: LEANDRO MARCUSSO | G52: EVERSON GAIDSTIECHI | H52: 0 | I52: 692.8 | J52: 700 | K52: 900 | M52: =Tabela1[[#This Row],[1ª QZ]]-Tabela1[[#This Row],[SALDO FINAL]]-Tabela1[[#This Row],[SALDO CARTAO]]-Tabela1[[#This Row],[Adiantamento ]] -> -892.8 | N52: =Tabela1[[#This Row],[SALDO REEMBOLSAR]]*$N$4 -> 0 | O52: 0 | Q52: =_xlfn.XLOOKUP(Tabela1[[#This Row],[COLABORADOR]],'STATUS CARTAO'!D:D,'STATUS CARTAO'!G:G) -> Cartão ativo
A53: BRUNO FERREIRA DE SOUZA RODRIGUES | B53: 16306431730 | C53: ATIVO | D53: REGIONAL RJ | E53: TELEFONICA RJ | F53: ALLAN JEFFERSON | G53: ROGERIO SCATAMBULO | H53: 0 | I53: 32541 | J53: 5000 | K53: 0.73 | M53: =Tabela1[[#This Row],[1ª QZ]]-Tabela1[[#This Row],[SALDO FINAL]]-Tabela1[[#This Row],[SALDO CARTAO]]-Tabela1[[#This Row],[Adiantamento ]] -> -27541.73 | N53: =Tabela1[[#This Row],[SALDO REEMBOLSAR]]*$N$4 -> 0 | O53: 0 | Q53: =_xlfn.XLOOKUP(Tabela1[[#This Row],[COLABORADOR]],'STATUS CARTAO'!D:D,'STATUS CARTAO'!G:G) -> Cartão ativo
A54: BRUNO OLIVEIRA DIAS | B54: 11992259755 | C54: ATIVO | D54: REGIONAL ES | E54: PTB TIC INFRA | F54: VINICIUS LOCATELLY | G54: MARCOS CARIAS | H54: 0 | I54: 7221.14 | J54: 6200 | K54: 2463.33 | M54: =Tabela1[[#This Row],[1ª QZ]]-Tabela1[[#This Row],[SALDO FINAL]]-Tabela1[[#This Row],[SALDO CARTAO]]-Tabela1[[#This Row],[Adiantamento ]] -> -3484.47 | N54: =Tabela1[[#This Row],[SALDO REEMBOLSAR]]*$N$4 -> 0 | O54: 0 | Q54: =_xlfn.XLOOKUP(Tabela1[[#This Row],[COLABORADOR]],'STATUS CARTAO'!D:D,'STATUS CARTAO'!G:G) -> Cartão ativo
A55: CAIO FRANCESCONI RIBEIRO | B55: 08924586904 | C55: ATIVO | D55: REGIONAL SC | E55: TJ APOIO PR | F55: LEANDRO MARCUSSO | G55: EVERSON GAIDSTIECHI | H55: 0 | I55: 3166.14 | J55: 3900 | K55: 4.82 | M55: =Tabela1[[#This Row],[1ª QZ]]-Tabela1[[#This Row],[SALDO FINAL]]-Tabela1[[#This Row],[SALDO CARTAO]]-Tabela1[[#This Row],[Adiantamento ]] -> 729.04 | N55: =Tabela1[[#This Row],[SALDO REEMBOLSAR]]*$N$4 -> 0 | O55: 729.04 | Q55: =_xlfn.XLOOKUP(Tabela1[[#This Row],[COLABORADOR]],'STATUS CARTAO'!D:D,'STATUS CARTAO'!G:G) -> Cartão ativo
...

Sheet Planilha1
B2: COLABORADOR | C2: CPF | D2: SITUAÇÃO | E2: REGIONAL | F2: CENTRO DE CUSTO | G2: COD. CENTRO DE CUSTO | H2: GESTOR | I2: Carga Final | K2: Rótulos de Linha | L2: Soma de Carga Final
B3: CHARLYTON COSTA ANDRADE | C3: 01050938232 | D3: ATIVO | E3: REGIONAL CO | F3: CEF AM AC RR | G3: 11030290001 | H3: ANGELICA SOARES | I3: 13149.29 | K3: 1201014 | L3: 926.515
B4: RAFAEL AMORIM VELLO | C4: 01677920599 | D4: ATIVO | E4: REGIONAL NE | F4: CEF NORTE OESTE BA | G4: 11030260001 | H4: GERSON OLIVEIRA | I4: 13690.57 | K4: 1201017 | L4: 388.93
B5: CARLOS RENATO PACHECO DA SILVA | C5: 90443306087 | D5: ATIVO | E5: REGIONAL RS | F5: CEF LESTE GAUCHO RS | G5: 11030580001 | H5: ALEXANDRE GROSS | I5: 3830.545 | K5: 1201020 | L5: 3000
B6: SANDRO BARRETO DE SOUZA | C6: 78021324953 | D6: ATIVO | E6: REGIONAL SC | F6: CEF SUL SC | G6: 11030700001 | H6: LEANDRO MARCUSSO | I6: 5250.44 | K6: 1201071 | L6: 1588.425
B7: CLAUDEMIR GREGOSKI RODRIGUES | C7: 05144026958 | D7: ATIVO | E7: REGIONAL SC | F7: CEF FACILITIES CURITIBA PR | G7: 11030860001 | H7: LEANDRO MARCUSSO | I7: 1950 | K7: 1104150001 | L7: 3110.3
B8: LEANDRO GUSMAO MUNIZ | C8: 13126691790 | D8: ATIVO | E8: REGIONAL RJ | F8: CEF INTERIOR RJ | G8: 11030870001 | H8: ALLAN JEFFERSON | I8: 2272.45 | K8: 11010060001 | L8: 738.48
B9: LUCAS MARTINS MACAN | C9: 00975748998 | D9: ATIVO | E9: REGIONAL NE | F9: CEF CEARA | G9: 11030890001 | H9: GERSON OLIVEIRA | I9: 3920.34 | K9: 11010080001 | L9: 751.5
B10: JOSE CARLOS BATISTA | C10: 26652452804 | D10: ATIVO | E10: REGIONAL SP | F10: PTB INFRA SUDESTE | G10: 11080170001 | H10: LEANDRO NUNES | I10: 5586.18 | K10: 11010110001 | L10: 843.82
B11: SAULO ARAUJO DE PAULA | C11: 31040091806 | D11: ATIVO | E11: REGIONAL SP | F11: CEF SP SUL | G11: 11030750001 | H11: LEANDRO NUNES | I11: 3319.26 | K11: 11010150001 | L11: 220
B12: VICTOR SIGOLO PINHEIRO PIMENTA | C12: 12237490619 | D12: ATIVO | E12: REGIONAL SP | F12: INSS SP | G12: 11062640001 | H12: LEANDRO NUNES | I12: 1856.69 | K12: 11010170001 | L12: 1787.705
B13: MARCO AURELIO DE ANDRADE MORAES | C13: 72756284220 | D13: ATIVO | E13: REGIONAL CO | F13: CEF AM AC RR | G13: 11030290001 | H13: ANGELICA SOARES | I13: 4685.92 | K13: 11010180001 | L13: 3315.12
B14: MARCELO GIMENEZ ARGEMON | C14: 95073272153 | D14: ATIVO | E14: REGIONAL SP | F14: CEF FACILITIES CAMPINAS SP | G14: 11030780001 | H14: LEANDRO NUNES | I14: 2622 | K14: 11010270001 | L14: 199.9
... B92: LUAN THIAGO DA SILVA | C92: 08030478437 | D92: ATIVO | E92: REGIONAL CLARO INFRA NORDESTE | F92: CLARO INFRA NORDESTE | G92: 11040170001 | H92: FELIPE JOSE | I92: 916.48 | K92: 11110340001 | L92: 920.18
B93: RICARDO ZORZETTO | C93: 00539580040 | D93: ATIVO | E93: REGIONAL RS | F93: CEF QUERENCIA RS | G93: 11030650001 | H93: ALEXANDRE GROSS | I93: 1305.025 | K93: Total Geral | L93: 268239.94
B94: WILLIAM NORONHA TEIXEIRA | C94: 02013700008 | D94: ATIVO | E94: REGIONAL RS | F94: NET APOIO RS | G94: 11061770001 | H94: ALEXANDRE GROSS | I94: 499.675
B95: RONALDO DE MATOS LELIS | C95: 47502843604 | D95: ATIVO | E95: REGIONAL MG | F95: CLARO INFRA MG | G95: 11040160001 | H95: HUGO ALEXANDRE | I95: 766.125
B96: JAEDER RODRIGUES JUNIOR | C96: 07505987607 | D96: ATIVO | E96: REGIONAL MG | F96: CEF NORDESTE MG | G96: 11030660001 | H96: HUGO ALEXANDRE | I96: 7264.135
B97: SILVIO VINICIUS PINHEIRO GOES | C97: 51182084168 | D97: ATIVO | E97: REGIONAL CO | F97: CLARO CO | G97: 11040040001 | H97: ANGELICA SOARES | I97: 298.08
B98: MARCIO BOUZAS FERREIRA | C98: 07318362780 | D98: ATIVO | E98: REGIONAL RJ | F98: VTAL CYBER RJ | G98: 11110340001 | H98: ALLAN JEFFERSON | I98: 920.18
B99: CLAUDINEI AMARAL | C99: 10433881844 | D99: ATIVO | E99: REGIONAL SC | F99: TRIBUNAL DE JUSTICA PR | G99: 11061720001 | H99: LEANDRO MARCUSSO | I99: 1095.285
B100: DIEGO JOSE DE PAULO | C100: 01553544692 | D100: ATIVO | E100: REGIONAL MG | F100: CLARO INFRA MG | G100: 11040160001 | H100: HUGO ALEXANDRE | I100: 1590.325
B101: ANDERSON BICA PEREZ | C101: 00053957040 | D101: ATIVO | E101: REGIONAL RS | F101: NET PORTO ALEGRE RS | G101: 11061820001 | H101: ALEXANDRE GROSS | I101: 678.795
B102: JAQUELINE ONORIO DOS SANTOS ALVES | C102: 37258325875 | D102: ATIVO | E102: REGIONAL SP | F102: TELEFONICA SP | G102: 11061420001 | H102: LEANDRO NUNES | I102: 1685.215
B103: AURO MOREIRA PEDROSO | C103: 32060157900 | D103: ATIVO | E103: REGIONAL SC | F103: BB NORTE OESTE PR | G103: 11010370001 | H103: LEANDRO MARCUSSO | I103: 740.305
B104: DANIEL SANTOS DE ASSUNCAO | C104: 97592439549 | D104: ATIVO | E104: REGIONAL NE | F104: BANCO ITAU BA | G104: 11062270001 | H104: GERSON OLIVEIRA | I104: 1661.21
B105: MOISES DOS SANTOS CABRAL | C105: 68746458204 | D105: ATIVO | E105: REGIONAL CO | F105: CEF FAC RO | G105: 11030810001 | H105: ANGELICA SOARES | I105: 541.35
... B170: ISAIAS DA SILVA | C170: 04083479965 | D170: ATIVO | E170: REGIONAL SC | F170: TRIBUNAL DE JUSTICA PR | G170: 11061720001 | H170: LEANDRO MARCUSSO | I170: 804.9
B171: SILVIO VINICIUS PINHEIRO GOES | C171: 51182084168 | E171: REGIONAL CO | F171: CLARO CO | G171: 11040040001 | I171: 5401.92
B172: FLAVIO FERNANDES DOS REIS LIMA | C172: 01767960107 | E172: REGIONAL CO | F172: TELEFONICA CO | G172: 11061430001 | I172: 3436.77
B173: WALTER DE CAMPOS NUNES NETO | C173: 99114160030 | E173: REGIONAL CLARO INFRA SUL | F173: CLARO INFRA RS | G173: 1104150001 | I173: 2810.3
B174: CAIOS VINICIUS NUNES BROERING | C174: 07053418952 | E174: REGIONAL CLARO INFRA SUL | F174: CLARO INFRA SC | G174: 11040130001 | I174: 2165.74
B175: JOELSON FERREIRA DOS SANTOS | C175: 07690263623 | E175: REGIONAL MG | F175: CEF SUDESTE MG | G175: 11060700001 | I175: 1816.75
B176: DANIEL DA SILVA LOPES | C176: 94288259053 | E176: REGIONAL SC | F176: NET APOIO SC | G176: 11061200001 | I176: 1741.55
B177: PAULO NILTON COSTA MOREIRA | C177: 45159599053 | E177: REGIONAL RS | F177: CEF EXTREMO SUL RS | G177: 11030590001 | I177: 1525.98
B178: PATRICK ANTONIEVICZ ALVES | C178: 06456801923 | E178: REGIONAL SC | F178: TRIBUNAL DE JUSTICA PR | G178: 11061720001 | I178: 1379
B179: FRANCIELLY FELIX CAVALCANTE DE ANDRADE | C179: 09276240446 | E179: REGIONAL CO | F179: CEF AM AC RR | G179: 11030290001 | I179: 1000
B180: LUCAS RODRIGUES DE MOURA GALVAO | C180: 04013986175 | E180: REGIONAL CO | F180: CEF GOIANIA CO | G180: 11030850001 | I180: 998.98
B181: EDUARDO SANTOS | C181: 91270529072 | E181: REGIONAL RS | F181: NET APOIO RS | G181: 11061770001 | I181: 964.99
B182: FABIO PROVESI | C182: 05731312958 | E182: REGIONAL SC | F182: BB SERET SC | G182: 11010180001 | I182: 668.02
...

Sheet RETIRAR
B2: COLABORADOR | C2: CPF | D2: SITUAÇÃO | E2: REGIONAL | F2: CENTRO DE CUSTO | G2: GESTOR | H2: DIRETOR | I2: SALDO REEMBOLSAR | J2: REEMBOLSO FEITO | K2: REEMBOLSO CORRETO | L2: RETIRAR
B3: CARLOS RENATO PACHECO DA SILVA | C3: 90443306087 | D3: ATIVO | E3: REGIONAL RS | F3: CEF LESTE GAUCHO RS | G3: ALEXANDRE GROSS | H3: EVERSON GAIDSTIECHI | I3: 2222.63 | J3: 1333.578 | K3: 1111.315 | L3: 222.263
B4: SANDRO BARRETO DE SOUZA | C4: 78021324953 | D4: ATIVO | E4: REGIONAL SC | F4: CEF SUL SC | G4: LEANDRO MARCUSSO | H4: EVERSON GAIDSTIECHI | I4: 2038.88 | J4: 1223.328 | K4: 1019.44 | L4: 203.888
B5: CLAUDEMIR GREGOSKI RODRIGUES | C5: 05144026958 | D5: ATIVO | E5: REGIONAL SC | F5: CEF FACILITIES CURITIBA PR | G5: LEANDRO MARCUSSO | H5: EVERSON GAIDSTIECHI | I5: 1900 | J5: 1140 | K5: 950 | L5: 190
B6: LEANDRO GUSMAO MUNIZ | C6: 13126691790 | D6: ATIVO | E6: REGIONAL RJ | F6: CEF INTERIOR RJ | G6: ALLAN JEFFERSON | H6: ROGERIO SCATAMBULO | I6: 1545 | J6: 927 | K6: 772.5 | L6: 154.5
B7: MARCELO GIMENEZ ARGEMON | C7: 95073272153 | D7: ATIVO | E7: REGIONAL SP | F7: CEF FACILITIES CAMPINAS SP | G7: LEANDRO NUNES | H7: EVERSON GAIDSTIECHI | I7: 1256 | J7: 753.6 | K7: 628 | L7: 125.6
B8: MARIA EDUARDA ARAGAO | C8: 10363402950 | D8: ATIVO | E8: REGIONAL SC | F8: CEF SUL SC | G8: LEANDRO MARCUSSO | H8: EVERSON GAIDSTIECHI | I8: 960.45 | J8: 576.27 | K8: 480.225 | L8: 96.045
B9: GUILHERME MOTTA RIBEIRO SILVA | C9: 11178519740 | D9: ATIVO | E9: REGIONAL ES | F9: CEF ES | G9: VINICIUS LOCATELLY | H9: MARCOS CARIAS | I9: 921.06 | J9: 552.636 | K9: 460.53 | L9: 92.106
B10: JUNIO VICENTE BARBOSA | C10: 10054353670 | D10: ATIVO | E10: REGIONAL MG | F10: CEF NORDESTE MG | G10: HUGO ALEXANDRE | H10: MARCOS CARIAS | I10: 848.61 | J10: 509.166 | K10: 424.305 | L10: 84.861
B11: TEOFILO TOLLENDAL PACHECO | C11: 26687333836 | D11: ATIVO | E11: REGIONAL SP | F11: TELEFONICA SP | G11: LEANDRO NUNES | H11: EVERSON GAIDSTIECHI | I11: 818.79 | J11: 491.274 | K11: 409.395 | L11: 81.879
B12: MARCELO DE ANDRADE CALVETTI | C12: 02587708052 | D12: ATIVO | E12: REGIONAL RS | F12: NET PORTO ALEGRE RS | G12: ALEXANDRE GROSS | H12: EVERSON GAIDSTIECHI | I12: 807.82 | J12: 484.692 | K12: 403.91 | L12: 80.782
B13: LEANDRO MARCUSSO | C13: 01857561902 | D13: ATIVO | E13: REGIONAL SC | F13: ADM FILIAL SC | G13: LEANDRO MARCUSSO | H13: EVERSON GAIDSTIECHI | I13: 806.09 | J13: 483.654 | K13: 403.045 | L13: 80.609
B14: JOSE JONAS FURLANETTO | C14: 55889913115 | D14: ATIVO | E14: REGIONAL SC | F14: BB NORTE OESTE PR | G14: LEANDRO MARCUSSO | H14: EVERSON GAIDSTIECHI | I14: 803.22 | J14: 481.932 | K14: 401.61 | L14: 80.322
... B59: ISAIAS DA SILVA | C59: 04083479965 | D59: ATIVO | E59: REGIONAL SC | F59: TRIBUNAL DE JUSTICA PR | G59: LEANDRO MARCUSSO | H59: EVERSON GAIDSTIECHI | I59: 10.02 | J59: 6.012 | K59: 5.01 | L59: 1.002

Sheet STATUS CARTAO
C2: Cobrança | D2: Nome | E2: E-mail | F2: Tipo de usuário | G2: Status do Cartão | H2: Permissão de Uso | I2: Permissão de Gestão | J2: Ações
D3: ABNER ANDRADE CAVALCANTE | E3: abner.cavalcante@eqsengenharia.com.br | F3: Normal | G3: Cartão ativo | H3: Portador de Cartão | I3: Sem permissão
D4: ADAN LEONARDO SOUZA BATISTA | E4: adan.batista@eqsengenharia.com.br | F4: Normal | G4: Cartão ativo | H4: Portador de Cartão | I4: Sem permissão
D5: ADAUTO JOSE PEREIRA | E5: adautojosepereira@yahoo.com.br | F5: Normal | G5: Cartão ativo | H5: Portador de Cartão | I5: Sem permissão
D6: ADEMARCIO DUARTE LOPES | E6: ctba_projetos@hotmail.com | F6: Normal | G6: Cartão ativo | H6: Portador de Cartão | I6: Sem permissão
D7: ADILSON ANTONIO JACINTO | E7: dirson4867@yahoo.com | F7: Normal | G7: Cartão ativo | H7: Portador de Cartão | I7: Sem permissão
D8: ADILSON MELLO DE CAMARGO | E8: adilsoncamargo@eqseng.com.br | F8: Normal | G8: Cartão ativo | H8: Portador de Cartão | I8: Sem permissão
D9: ADILSON RODRIGUES FERREIRA | E9: adilson.ferreira@eqsengenharia.com.br | F9: Intermediário | G9: Cadastro pendente | H9: Portador de Cartão | I9: Sem permissão
D10: ADIVAR ANTONIO DA SILVA JUNIOR | E10: adivarjunior@gmail.com | F10: Normal | G10: Cartão ativo | H10: Portador de Cartão | I10: Sem permissão
D11: ADMILSON DA SILVA FARIAS | E11: admilsonfarias2016@gmail.com | F11: Normal | G11: Cadastro pendente | H11: Portador de Cartão | I11: Sem permissão
D12: ADMILSON DOS SANTOS GALAN | E12: admilsongalan@gmail.com | F12: Normal | G12: Cartão ativo | H12: Portador de Cartão | I12: Sem permissão
D13: ADRIANA DA CONCEICAO PEREIRA DE MELO | E13: adriana.melo@eqsengenharia.com.br | F13: Normal | G13: Cadastro pendente | H13: Portador de Cartão | I13: Sem permissão
D14: ADRIANE CARON | E14: adriane.caron@eqseng.com.br | F14: Normal | G14: Cartão ativo | H14: Portador de Cartão | I14: Sem permissão
... D52: ANDRE ARANHA MEISTER | E52: andre.meister@eqsengenharia.com.br | F52: Normal | G52: Cartão ativo | H52: Portador de Cartão | I52: Sem permissão
C53: Cobrança | D53: Nome | E53: E-mail | F53: Tipo de usuário | G53: Status do Cartão | H53: Permissão de Uso | I53: Permissão de Gestão | J53: Ações
D54: ANDRE DE MOURA ESCOBAR | E54: andre.escobar@eqseng.com.br | F54: Normal | G54: Cartão ativo | H54: Portador de Cartão | I54: Sem permissão
D55: ANDRE LUIZ DOS SANTOS OLIVEIRA | E55: andre.oliveira.supervisor.telecom@gmail.com | F55: Normal | G55: Cadastro pendente | H55: Portador de Cartão | I55: Sem permissão
D56: ANDRE LUIZ SANTANA | E56: andre.santana@eqsengenharia.com.br | F56: Normal | G56: Cartão ativo | H56: Portador de Cartão | I56: Sem permissão
D57: ANDRE PINHEIRO BALOTIN | E57: andre.balotin@eqsengenharia.com.br | F57: Normal | G57: Cartão ativo | H57: Portador de Cartão | I57: Sem permissão
D58: ANDRE VALERIO DE PAIVA | E58: toxcroen@gmail.com | F58: Normal | G58: Cartão ativo | H58: Portador de Cartão | I58: Sem permissão
D59: ANDREA ANTUNES GOMES | E59: andrea.antunes@eqsengenharia.com.br | F59: Normal | G59: Cartão ativo | H59: Portador de Cartão | I59: Sem permissão
D60: ANDRESA INDIRA SANTANA AGGIO | E60: andresa.aggio@eqsengenharia.com.br | F60: Normal | G60: Cartão ativo | H60: Portador de Cartão | I60: Sem permissão
D61: ANDREY CARDOSO REGINALDO | E61: andrey.reginaldo@eqsengenharia.com.br | F61: Administrador | G61: Cadastro pendente | H61: Portador de Cartão | I61: Gestor de Contas
D62: ANELISE MENDONCA DE AVILA | E62: anelise@eqsengenharia.com.br | F62: Normal | G62: Cartão ativo | H62: Portador de Cartão | I62: Sem permissão
D63: Angelica Sampaio Sousa | E63: angelica.sousa@eqsengenharia.com.br | F63: Normal | G63: Cartão ativo | H63: Portador de Cartão | I63: Sem permissão
D64: ANGELICA SOARES AMARANTE SILVA | E64: angelica.amarante@eqsengenharia.com.br | F64: Intermediário | G64: Cartão ativo | H64: Portador de Cartão | I64: Sem permissão
D65: ANTONIO DE PADUA LEITE | E65: antonio@eqseng.com.br | F65: Normal | G65: Cartão ativo | H65: Portador de Cartão | I65: Sem permissão
... D103: CHARLES NEVES MATTIUZZI | E103: cmattyuzzy@gmail.com | F103: Normal | G103: Cartão ativo | H103: Portador de Cartão | I103: Sem permissão
C104: Cobrança | D104: Nome | E104: E-mail | F104: Tipo de usuário | G104: Status do Cartão | H104: Permissão de Uso | I104: Permissão de Gestão | J104: Ações
D105: CHARLYTON COSTA ANDRADE | E105: charlyton.andrade@eqsengenharia.com.br | F105: Normal | G105: Cartão ativo | H105: Portador de Cartão | I105: Sem permissão
D106: CINTIA DOS SANTOS RABELO | E106: cintia.rabelo@eqsengenharia.com.br | F106: Normal | G106: Cartão ativo | H106: Portador de Cartão | I106: Sem permissão
D107: CLAUDEMIR GREGOSKI RODRIGUES | E107: claudemir.rodrigues@eqsengenharia.com.br | F107: Normal | G107: Cartão ativo | H107: Portador de Cartão | I107: Sem permissão
D108: CLAUDEMIR MOREIRA | E108: claudemir.moreura054@gmail.com | F108: Normal | G108: Cartão ativo | H108: Portador de Cartão | I108: Sem permissão
D109: CLAUDINEI AMARAL | E109: amaralclaudinei@hotmail.com | F109: Normal | G109: Cartão ativo | H109: Portador de Cartão | I109: Sem permissão
D110: CLAUDINEI VICENTE DE LIMA | E110: claudinei.lima@eqsengenharia.com.br | F110: Normal | G110: Cartão ativo | H110: Portador de Cartão | I110: Sem permissão
D111: CLAUDIO DONIZETE DA SILVA | E111: claudiodonizete8321@gmail.com | F111: Normal | G111: Cartão ativo | H111: Portador de Cartão | I111: Sem permissão
D112: CLAUDIO RENALDI NUNES | E112: clrenaldinunes@gmail.com | F112: Normal | G112: Cartão ativo | H112: Portador de Cartão | I112: Sem permissão
D113: CLAYTON DE OLIVEIRA | E113: claytonpr@gmail.com | F113: Normal | G113: Cartão ativo | H113: Portador de Cartão | I113: Sem permissão
D114: CLEBERSON APARECIDO BORGES DOS SANTOS | E114: binhoclebersonsantos@gmail.com | F114: Normal | G114: Cartão ativo | H114: Portador de Cartão | I114: Sem permissão
D115: CLEDIVALDO DINIZ BERNARDO | E115: DINIZCLEDIVALDO@GMAIL.COM | F115: Normal | G115: Cartão não habilitado | H115: Sem permissão | I115: Sem permissão
...
