Workbook

Sheet FECHAMENTO
B4: FECHAMENTO DE PRESTAÇÃO DE CONTAS
B6: BEATRIZ SILVA DE SIQUEIRA
B7: Ano | C7: Mês | D7: Carga | E7: Transferência | F7: Taxa | G7: Prest. Contas | H7: Saldo | I7: Acumulado | K7: STATUS | L7: VALOR
B8: 2025 | C8: MAIO | D8: =SUMIFS(EXTRATO!I:I,EXTRATO!G:G,FECHAMENTO!$D$7,EXTRATO!B:B,FECHAMENTO!C8,EXTRATO!A:A,FECHAMENTO!B8) -> 1183.02 | E8: =SUMIFS(EXTRATO!I:I,EXTRATO!G:G,FECHAMENTO!$E$7,EXTRATO!B:B,FECHAMENTO!C8,EXTRATO!A:A,FECHAMENTO!B8) -> 0 | F8: =SUMIFS(EXTRATO!I:I,EXTRATO!G:G,FECHAMENTO!$F$7,EXTRATO!B:B,FECHAMENTO!C8,EXTRATO!A:A,FECHAMENTO!B8) -> 0 | G8: =SUMIFS('PREST. CONTAS'!AB:AB,'PREST. CONTAS'!B:B,FECHAMENTO!C8,'PREST. CONTAS'!A:A,FECHAMENTO!B8,'PREST. CONTAS'!I:I,"<>Aberto",'PREST. CONTAS'!I:I,"<>Reprovado") -> 215.69 | H8: =D8+E8+F8-G8 -> 967.33 | I8: =H8 -> 967.33 | K8: Aberto | L8: 2082.4
B9: 2025 | C9: JUNHO | D9: =SUMIFS(EXTRATO!I:I,EXTRATO!G:G,FECHAMENTO!$D$7,EXTRATO!B:B,FECHAMENTO!C9,EXTRATO!A:A,FECHAMENTO!B9) -> 1210.98 | E9: =SUMIFS(EXTRATO!I:I,EXTRATO!G:G,FECHAMENTO!$E$7,EXTRATO!B:B,FECHAMENTO!C9,EXTRATO!A:A,FECHAMENTO!B9) -> 0 | F9: =SUMIFS(EXTRATO!I:I,EXTRATO!G:G,FECHAMENTO!$F$7,EXTRATO!B:B,FECHAMENTO!C9,EXTRATO!A:A,FECHAMENTO!B9) -> -21 | G9: =SUMIFS('PREST. CONTAS'!AB:AB,'PREST. CONTAS'!B:B,C9,'PREST. CONTAS'!A:A,B9,'PREST. CONTAS'!I:I,"<>Aberto",'PREST. CONTAS'!I:I,"<>Reprovado") -> 983.32 | H9: =D9+E9+F9-G9 -> 206.66 | I9: =H9+I8 -> 1173.99 | K9: Aprovado | L9: 24955.93
B10: 2025 | C10: JULHO | D10: =SUMIFS(EXTRATO!I:I,EXTRATO!G:G,FECHAMENTO!$D$7,EXTRATO!B:B,FECHAMENTO!C10,EXTRATO!A:A,FECHAMENTO!B10) -> 2953.46 | E10: =SUMIFS(EXTRATO!I:I,EXTRATO!G:G,FECHAMENTO!$E$7,EXTRATO!B:B,FECHAMENTO!C10,EXTRATO!A:A,FECHAMENTO!B10) -> 0 | F10: =SUMIFS(EXTRATO!I:I,EXTRATO!G:G,FECHAMENTO!$F$7,EXTRATO!B:B,FECHAMENTO!C10,EXTRATO!A:A,FECHAMENTO!B10) -> -28 | G10: =SUMIFS('PREST. CONTAS'!AB:AB,'PREST. CONTAS'!B:B,C10,'PREST. CONTAS'!A:A,B10,'PREST. CONTAS'!I:I,"<>Aberto",'PREST. CONTAS'!I:I,"<>Reprovado") -> 1553.88 | H10: =D10+E10+F10-G10 -> 1371.58 | I10: =H10+I9 -> 2545.57 | K10: Total Geral | L10: 27038.33
B11: 2025 | C11: AGOSTO | D11: =SUMIFS(EXTRATO!I:I,EXTRATO!G:G,FECHAMENTO!$D$7,EXTRATO!B:B,FECHAMENTO!C11,EXTRATO!A:A,FECHAMENTO!B11) -> 0 | E11: =SUMIFS(EXTRATO!I:I,EXTRATO!G:G,FECHAMENTO!$E$7,EXTRATO!B:B,FECHAMENTO!C11,EXTRATO!A:A,FECHAMENTO!B11) -> 0 | F11: =SUMIFS(EXTRATO!I:I,EXTRATO!G:G,FECHAMENTO!$F$7,EXTRATO!B:B,FECHAMENTO!C11,EXTRATO!A:A,FECHAMENTO!B11) -> 0 | G11: =SUMIFS('PREST. CONTAS'!AB:AB,'PREST. CONTAS'!B:B,C11,'PREST. CONTAS'!A:A,B11,'PREST. CONTAS'!I:I,"<>Aberto",'PREST. CONTAS'!I:I,"<>Reprovado") -> 2352.96 | H11: =D11+E11+F11-G11 -> -2352.96 | I11: =H11+I10 -> 192.61
B12: 2025 | C12: SETEMBRO | D12: =SUMIFS(EXTRATO!I:I,EXTRATO!G:G,FECHAMENTO!$D$7,EXTRATO!B:B,FECHAMENTO!C12,EXTRATO!A:A,FECHAMENTO!B12) -> 4195.54 | E12: =SUMIFS(EXTRATO!I:I,EXTRATO!G:G,FECHAMENTO!$E$7,EXTRATO!B:B,FECHAMENTO!C12,EXTRATO!A:A,FECHAMENTO!B12) -> 0 | F12: =SUMIFS(EXTRATO!I:I,EXTRATO!G:G,FECHAMENTO!$F$7,EXTRATO!B:B,FECHAMENTO!C12,EXTRATO!A:A,FECHAMENTO!B12) -> -28 | G12: =SUMIFS('PREST. CONTAS'!AB:AB,'PREST. CONTAS'!B:B,C12,'PREST. CONTAS'!A:A,B12,'PREST. CONTAS'!I:I,"<>Aberto",'PREST. CONTAS'!I:I,"<>Reprovado") -> 2698.15 | H12: =D12+E12+F12-G12 -> 1469.39 | I12: =H12+I11 -> 1662
B13: 2025 | C13: OUTUBRO | D13: =SUMIFS(EXTRATO!I:I,EXTRATO!G:G,FECHAMENTO!$D$7,EXTRATO!B:B,FECHAMENTO!C13,EXTRATO!A:A,FECHAMENTO!B13) -> 2957.62 | E13: =SUMIFS(EXTRATO!I:I,EXTRATO!G:G,FECHAMENTO!$E$7,EXTRATO!B:B,FECHAMENTO!C13,EXTRATO!A:A,FECHAMENTO!B13) -> 0 | F13: =SUMIFS(EXTRATO!I:I,EXTRATO!G:G,FECHAMENTO!$F$7,EXTRATO!B:B,FECHAMENTO!C13,EXTRATO!A:A,FECHAMENTO!B13) -> -28 | G13: =SUMIFS('PREST. CONTAS'!AB:AB,'PREST. CONTAS'!B:B,C13,'PREST. CONTAS'!A:A,B13,'PREST. CONTAS'!I:I,"<>Aberto",'PREST. CONTAS'!I:I,"<>Reprovado") -> 2527.06 | H13: =D13+E13+F13-G13 -> 402.56 | I13: =H13+I12 -> 2064.56
B14: 2025 | C14: NOVEMBRO | D14: =SUMIFS(EXTRATO!I:I,EXTRATO!G:G,FECHAMENTO!$D$7,EXTRATO!B:B,FECHAMENTO!C14,EXTRATO!A:A,FECHAMENTO!B14) -> 688.07 | E14: =SUMIFS(EXTRATO!I:I,EXTRATO!G:G,FECHAMENTO!$E$7,EXTRATO!B:B,FECHAMENTO!C14,EXTRATO!A:A,FECHAMENTO!B14) -> 0 | F14: =SUMIFS(EXTRATO!I:I,EXTRATO!G:G,FECHAMENTO!$F$7,EXTRATO!B:B,FECHAMENTO!C14,EXTRATO!A:A,FECHAMENTO!B14) -> -7 | G14: =SUMIFS('PREST. CONTAS'!AB:AB,'PREST. CONTAS'!B:B,C14,'PREST. CONTAS'!A:A,B14,'PREST. CONTAS'!I:I,"<>Aberto",'PREST. CONTAS'!I:I,"<>Reprovado") -> 2044.35 | H14: =D14+E14+F14-G14 -> -1363.28 | I14: =H14+I13 -> 701.28
B15: 2025 | C15: DEZEMBRO | D15: =SUMIFS(EXTRATO!I:I,EXTRATO!G:G,FECHAMENTO!$D$7,EXTRATO!B:B,FECHAMENTO!C15,EXTRATO!A:A,FECHAMENTO!B15) -> 1588.74 | E15: =SUMIFS(EXTRATO!I:I,EXTRATO!G:G,FECHAMENTO!$E$7,EXTRATO!B:B,FECHAMENTO!C15,EXTRATO!A:A,FECHAMENTO!B15) -> 0 | F15: =SUMIFS(EXTRATO!I:I,EXTRATO!G:G,FECHAMENTO!$F$7,EXTRATO!B:B,FECHAMENTO!C15,EXTRATO!A:A,FECHAMENTO!B15) -> -14 | G15: =SUMIFS('PREST. CONTAS'!AB:AB,'PREST. CONTAS'!B:B,C15,'PREST. CONTAS'!A:A,B15,'PREST. CONTAS'!I:I,"<>Aberto",'PREST. CONTAS'!I:I,"<>Reprovado") -> 2448.35 | H15: =D15+E15+F15-G15 -> -873.61 | I15: =H15+I14 -> -172.33
B16: 2026 | C16: JANEIRO | D16: =SUMIFS(EXTRATO!I:I,EXTRATO!G:G,FECHAMENTO!$D$7,EXTRATO!B:B,FECHAMENTO!C16,EXTRATO!A:A,FECHAMENTO!B16) -> 4306 | E16: =SUMIFS(EXTRATO!I:I,EXTRATO!G:G,FECHAMENTO!$E$7,EXTRATO!B:B,FECHAMENTO!C16,EXTRATO!A:A,FECHAMENTO!B16) -> -6.43 | F16: =SUMIFS(EXTRATO!I:I,EXTRATO!G:G,FECHAMENTO!$F$7,EXTRATO!B:B,FECHAMENTO!C16,EXTRATO!A:A,FECHAMENTO!B16) -> -35 | G16: =SUMIFS('PREST. CONTAS'!AB:AB,'PREST. CONTAS'!B:B,C16,'PREST. CONTAS'!A:A,B16,'PREST. CONTAS'!I:I,"<>Aberto",'PREST. CONTAS'!I:I,"<>Reprovado") -> 1845.73 | H16: =D16+E16+F16-G16 -> 2418.84 | I16: =H16+I15 -> 2246.51
B17: 2026 | C17: FEVEREIRO | D17: =SUMIFS(EXTRATO!I:I,EXTRATO!G:G,FECHAMENTO!$D$7,EXTRATO!B:B,FECHAMENTO!C17,EXTRATO!A:A,FECHAMENTO!B17) -> 2013.46 | E17: =SUMIFS(EXTRATO!I:I,EXTRATO!G:G,FECHAMENTO!$E$7,EXTRATO!B:B,FECHAMENTO!C17,EXTRATO!A:A,FECHAMENTO!B17) -> 0 | F17: =SUMIFS(EXTRATO!I:I,EXTRATO!G:G,FECHAMENTO!$F$7,EXTRATO!B:B,FECHAMENTO!C17,EXTRATO!A:A,FECHAMENTO!B17) -> -21 | G17: =SUMIFS('PREST. CONTAS'!AB:AB,'PREST. CONTAS'!B:B,C17,'PREST. CONTAS'!A:A,B17,'PREST. CONTAS'!I:I,"<>Aberto",'PREST. CONTAS'!I:I,"<>Reprovado") -> 2889.99 | H17: =D17+E17+F17-G17 -> -897.53 | I17: =H17+I16 -> 1348.98
B18: 2026 | C18: MARÇO | D18: =SUMIFS(EXTRATO!I:I,EXTRATO!G:G,FECHAMENTO!$D$7,EXTRATO!B:B,FECHAMENTO!C18,EXTRATO!A:A,FECHAMENTO!B18) -> 1812.44 | E18: =SUMIFS(EXTRATO!I:I,EXTRATO!G:G,FECHAMENTO!$E$7,EXTRATO!B:B,FECHAMENTO!C18,EXTRATO!A:A,FECHAMENTO!B18) -> 0 | F18: =SUMIFS(EXTRATO!I:I,EXTRATO!G:G,FECHAMENTO!$F$7,EXTRATO!B:B,FECHAMENTO!C18,EXTRATO!A:A,FECHAMENTO!B18) -> -14 | G18: =SUMIFS('PREST. CONTAS'!AB:AB,'PREST. CONTAS'!B:B,C18,'PREST. CONTAS'!A:A,B18,'PREST. CONTAS'!I:I,"<>Aberto",'PREST. CONTAS'!I:I,"<>Reprovado") -> 1925.92 | H18: =D18+E18+F18-G18 -> -127.48 | I18: =H18+I17 -> 1221.5
B19: 2026 | C19: ABRIL | D19: =SUMIFS(EXTRATO!I:I,EXTRATO!G:G,FECHAMENTO!$D$7,EXTRATO!B:B,FECHAMENTO!C19,EXTRATO!A:A,FECHAMENTO!B19) -> 1810.16 | E19: =SUMIFS(EXTRATO!I:I,EXTRATO!G:G,FECHAMENTO!$E$7,EXTRATO!B:B,FECHAMENTO!C19,EXTRATO!A:A,FECHAMENTO!B19) -> 0 | F19: =SUMIFS(EXTRATO!I:I,EXTRATO!G:G,FECHAMENTO!$F$7,EXTRATO!B:B,FECHAMENTO!C19,EXTRATO!A:A,FECHAMENTO!B19) -> -14 | G19: =SUMIFS('PREST. CONTAS'!AB:AB,'PREST. CONTAS'!B:B,C19,'PREST. CONTAS'!A:A,B19,'PREST. CONTAS'!I:I,"<>Aberto",'PREST. CONTAS'!I:I,"<>Reprovado") -> 1434.83 | H19: =D19+E19+F19-G19 -> 361.33 | I19: =H19+I18 -> 1582.83
B20: 2026 | C20: MAIO | D20: =SUMIFS(EXTRATO!I:I,EXTRATO!G:G,FECHAMENTO!$D$7,EXTRATO!B:B,FECHAMENTO!C20,EXTRATO!A:A,FECHAMENTO!B20) -> 1594.15 | E20: =SUMIFS(EXTRATO!I:I,EXTRATO!G:G,FECHAMENTO!$E$7,EXTRATO!B:B,FECHAMENTO!C20,EXTRATO!A:A,FECHAMENTO!B20) -> 0 | F20: =SUMIFS(EXTRATO!I:I,EXTRATO!G:G,FECHAMENTO!$F$7,EXTRATO!B:B,FECHAMENTO!C20,EXTRATO!A:A,FECHAMENTO!B20) -> -28 | G20: =SUMIFS('PREST. CONTAS'!AB:AB,'PREST. CONTAS'!B:B,C20,'PREST. CONTAS'!A:A,B20,'PREST. CONTAS'!I:I,"<>Aberto",'PREST. CONTAS'!I:I,"<>Reprovado") -> 1178.31 | H20: =D20+E20+F20-G20 -> 387.84 | I20: =H20+I19 -> 1970.67
B21: 2026 | C21: JUNHO | D21: =SUMIFS(EXTRATO!I:I,EXTRATO!G:G,FECHAMENTO!$D$7,EXTRATO!B:B,FECHAMENTO!C21,EXTRATO!A:A,FECHAMENTO!B21) -> 391.86 | E21: =SUMIFS(EXTRATO!I:I,EXTRATO!G:G,FECHAMENTO!$E$7,EXTRATO!B:B,FECHAMENTO!C21,EXTRATO!A:A,FECHAMENTO!B21) -> 0 | F21: =SUMIFS(EXTRATO!I:I,EXTRATO!G:G,FECHAMENTO!$F$7,EXTRATO!B:B,FECHAMENTO!C21,EXTRATO!A:A,FECHAMENTO!B21) -> -7 | G21: =SUMIFS('PREST. CONTAS'!AB:AB,'PREST. CONTAS'!B:B,C21,'PREST. CONTAS'!A:A,B21,'PREST. CONTAS'!I:I,"<>Aberto",'PREST. CONTAS'!I:I,"<>Reprovado") -> 857.39 | H21: =D21+E21+F21-G21 -> -472.53 | I21: =H21+I20 -> 1498.14
B22: 2026 | C22: JULHO | D22: =SUMIFS(EXTRATO!I:I,EXTRATO!G:G,FECHAMENTO!$D$7,EXTRATO!B:B,FECHAMENTO!C22,EXTRATO!A:A,FECHAMENTO!B22) -> 985.93 | E22: =SUMIFS(EXTRATO!I:I,EXTRATO!G:G,FECHAMENTO!$E$7,EXTRATO!B:B,FECHAMENTO!C22,EXTRATO!A:A,FECHAMENTO!B22) -> 0 | F22: =SUMIFS(EXTRATO!I:I,EXTRATO!G:G,FECHAMENTO!$F$7,EXTRATO!B:B,FECHAMENTO!C22,EXTRATO!A:A,FECHAMENTO!B22) -> -7 | G22: =SUMIFS('PREST. CONTAS'!AB:AB,'PREST. CONTAS'!B:B,C22,'PREST. CONTAS'!A:A,B22,'PREST. CONTAS'!I:I,"<>Aberto",'PREST. CONTAS'!I:I,"<>Reprovado") -> 0 | H22: =D22+E22+F22-G22 -> 978.93 | I22: =H22+I21 -> 2477.07
D23: =SUM(D8:D22) -> 27691.43 | E23: =SUM(E8:E22) -> -6.43 | F23: =SUM(F8:F22) -> -252 | G23: =SUM(G8:G22) -> 24955.93 | H23: =SUM(H8:H22) -> 2477.07
B25: SALDO FINAL | H25: =H23 -> 2477.07 | K25: LEGENDA SINAIS
B26: (+) SALDO DISPONIVEL | H26: =D23+E23+F23 -> 27433 | K26: NEGATIVO | L26: A REEMBOLSAR
B27: (-) PRESTAÇÃO DE CONTAS | H27: =G23 -> 24955.93 | K27: POSITIVO | L27: A PRESTAR
B28: = FECHAMENTO PRESTE CONTAS | H28: =H26-H27 -> 2477.07
B29: = SALDO CARTÃO | H29: 3
B30: FECHAMENTO FINAL - SALDO PENDENTE | H30: =H28-H29 -> 2474.07

Sheet PREST. CONTAS
A1: Ano | B1: Mês | C1: ID da Despesa | D1: ID do Relatório | E1: Nome do relatório | F1: Data | G1: Nome do membro de equipe | H1: CPF/CNPJ | I1: Status | J1: Data de Pagamento | K1: Descrição da despesa | L1: Tipo de Despesa | M1: Reembolsável | N1: Anotação da Despesa | O1: Anotação de Rateio | P1: Centro de Custos | Q1: Forma de pagamento | R1: Projeto | S1: Percentual de projeto | T1: Início do Percurso por GPS | U1: Fim do Percurso por GPS | V1: Valor do KM | W1: Kilômetros Percorridos | X1: Moeda do Relatório | Y1: Valor | Z1: Moeda da Conversão | AA1: Valor Convertido | AB1: Valor Total | AC1: Ultrapassou Política
A2: =YEAR(F2) -> 2026 | B2: =UPPER(TEXT(F2,"MMMM")) -> JULHO | C2: 87556404 | D2: 10906730 | E2: CAIXA 07/2026 | F2: 46227 | G2: BEATRIZ SILVA DE SIQUEIRA | H2: 35575473880 | I2: Aberto | K2: Material | L2: MATERIAL | M2: Não | N2: Atendimento de chamado caixa economica | P2: CEF SP SUL | Q2: Saque VExpenses | R2: REGIONAL SP | S2: 1 | X2: BRL | Y2: 45 | AB2: 45 | AC2: Não
A3: =YEAR(F3) -> 2026 | B3: =UPPER(TEXT(F3,"MMMM")) -> JULHO | C3: 87002054 | D3: 10906730 | E3: CAIXA 07/2026 | F3: 46221 | G3: BEATRIZ SILVA DE SIQUEIRA | H3: 35575473880 | I3: Aberto | K3: Material | L3: MATERIAL | M3: Não | N3: Atendimento de chamado caixa economica | P3: CEF SP SUL | Q3: Saque VExpenses | R3: REGIONAL SP | S3: 1 | X3: BRL | Y3: 74.5 | AB3: 74.5 | AC3: Não
A4: =YEAR(F4) -> 2026 | B4: =UPPER(TEXT(F4,"MMMM")) -> JULHO | C4: 87001977 | D4: 10906730 | E4: CAIXA 07/2026 | F4: 46221 | G4: BEATRIZ SILVA DE SIQUEIRA | H4: 35575473880 | I4: Aberto | K4: Material | L4: MATERIAL | M4: Não | N4: Atendimento de chamado caixa economica | P4: CEF SP SUL | Q4: Saque VExpenses | R4: REGIONAL SP | S4: 1 | X4: BRL | Y4: 83.1 | AB4: 83.1 | AC4: Não
A5: =YEAR(F5) -> 2026 | B5: =UPPER(TEXT(F5,"MMMM")) -> JULHO | C5: 87001778 | D5: 10906730 | E5: CAIXA 07/2026 | F5: 46221 | G5: BEATRIZ SILVA DE SIQUEIRA | H5: 35575473880 | I5: Aberto | K5: Material | L5: MATERIAL | M5: Não | N5: Atendimento de chamado caixa economica | P5: CEF SP SUL | Q5: Saque VExpenses | R5: REGIONAL SP | S5: 1 | X5: BRL | Y5: 62.8 | AB5: 62.8 | AC5: Não
A6: =YEAR(F6) -> 2026 | B6: =UPPER(TEXT(F6,"MMMM")) -> JULHO | C6: 87001416 | D6: 10906730 | E6: CAIXA 07/2026 | F6: 46221 | G6: BEATRIZ SILVA DE SIQUEIRA | H6: 35575473880 | I6: Aberto | K6: Material | L6: MATERIAL | M6: Não | N6: Atendimento de chamado caixa economica | P6: CEF SP SUL | Q6: Saque VExpenses | R6: REGIONAL SP | S6: 1 | X6: BRL | Y6: 53.33 | AB6: 53.33 | AC6: Não
A7: =YEAR(F7) -> 2026 | B7: =UPPER(TEXT(F7,"MMMM")) -> JULHO | C7: 87002136 | D7: 10906730 | E7: CAIXA 07/2026 | F7: 46220 | G7: BEATRIZ SILVA DE SIQUEIRA | H7: 35575473880 | I7: Aberto | K7: Material | L7: MATERIAL | M7: Não | N7: Atendimento de chamado caixa economica | P7: CEF SP SUL | Q7: Saque VExpenses | R7: REGIONAL SP | S7: 1 | X7: BRL | Y7: 51.21 | AB7: 51.21 | AC7: Não
A8: =YEAR(F8) -> 2026 | B8: =UPPER(TEXT(F8,"MMMM")) -> JULHO | C8: 87001089 | D8: 10906730 | E8: CAIXA 07/2026 | F8: 46217 | G8: BEATRIZ SILVA DE SIQUEIRA | H8: 35575473880 | I8: Aberto | K8: Material | L8: MATERIAL | M8: Não | N8: Atendimento de chamado caixa economica | P8: CEF SP SUL | Q8: Saque VExpenses | R8: REGIONAL SP | S8: 1 | X8: BRL | Y8: 110 | AB8: 110 | AC8: Não
A9: =YEAR(F9) -> 2026 | B9: =UPPER(TEXT(F9,"MMMM")) -> JULHO | C9: 87000987 | D9: 10906730 | E9: CAIXA 07/2026 | F9: 46216 | G9: BEATRIZ SILVA DE SIQUEIRA | H9: 35575473880 | I9: Aberto | K9: Material | L9: MATERIAL | M9: Não | N9: Atendimento de chamado caixa economica | P9: CEF SP SUL | Q9: Saque VExpenses | R9: REGIONAL SP | S9: 1 | X9: BRL | Y9: 25 | AB9: 25 | AC9: Não
A10: =YEAR(F10) -> 2026 | B10: =UPPER(TEXT(F10,"MMMM")) -> JULHO | C10: 87001218 | D10: 10906730 | E10: CAIXA 07/2026 | F10: 46210 | G10: BEATRIZ SILVA DE SIQUEIRA | H10: 35575473880 | I10: Aberto | K10: Material | L10: MATERIAL | M10: Não | N10: Atendimento de chamado caixa economica | P10: CEF SP SUL | Q10: Saque VExpenses | R10: REGIONAL SP | S10: 1 | X10: BRL | Y10: 6 | AB10: 6 | AC10: Não
A11: =YEAR(F11) -> 2026 | B11: =UPPER(TEXT(F11,"MMMM")) -> JULHO | C11: 87001310 | D11: 10906730 | E11: CAIXA 07/2026 | F11: 46209 | G11: BEATRIZ SILVA DE SIQUEIRA | H11: 35575473880 | I11: Aberto | K11: Material | L11: MATERIAL | M11: Não | N11: Atendimento de chamado caixa economica | P11: CEF SP SUL | Q11: Saque VExpenses | R11: REGIONAL SP | S11: 1 | X11: BRL | Y11: 40 | AB11: 40 | AC11: Não
A12: =YEAR(F12) -> 2026 | B12: =UPPER(TEXT(F12,"MMMM")) -> JULHO | C12: 86328704 | D12: 10906730 | E12: CAIXA 07/2026 | F12: 46207 | G12: BEATRIZ SILVA DE SIQUEIRA | H12: 35575473880 | I12: Aberto | K12: Nota 7 | L12: MATERIAL | M12: Não | N12: Nota 7 | P12: CEF SP SUL | Q12: Saque VExpenses | R12: REGIONAL SP | S12: 1 | X12: BRL | Y12: 31 | AB12: 31 | AC12: Não
A13: =YEAR(F13) -> 2026 | B13: =UPPER(TEXT(F13,"MMMM")) -> JULHO | C13: 86057697 | D13: 10906730 | E13: CAIXA 07/2026 | F13: 46206 | G13: BEATRIZ SILVA DE SIQUEIRA | H13: 35575473880 | I13: Aberto | K13: Nota 02 | L13: MATERIAL | M13: Não | N13: Nota 2 | P13: CEF SP SUL | Q13: Saque VExpenses | R13: REGIONAL SP | S13: 1 | X13: BRL | Y13: 60 | AB13: 60 | AC13: Não
... A19: =YEAR(F19) -> 2026 | B19: =UPPER(TEXT(F19,"MMMM")) -> JUNHO | C19: 87146033 | D19: 10906730 | E19: CAIXA 07/2026 | F19: 46198 | G19: BEATRIZ SILVA DE SIQUEIRA | H19: 35575473880 | I19: Aberto | K19: MATERIAL | L19: MATERIAL | M19: Não | N19: Atendimento de chamado caixa economica | P19: CEF SP SUL | Q19: Saque VExpenses | R19: REGIONAL SP | S19: 1 | X19: BRL | Y19: 70 | AB19: 70 | AC19: Não
A20: =YEAR(F20) -> 2026 | B20: =UPPER(TEXT(F20,"MMMM")) -> JUNHO | C20: 87144760 | D20: 10906730 | E20: CAIXA 07/2026 | F20: 46189 | G20: BEATRIZ SILVA DE SIQUEIRA | H20: 35575473880 | I20: Aberto | K20: Material | L20: MATERIAL | M20: Não | N20: A nota fiscal foi anexada ao cartão de crédito de forma equivocada. Esclarecemos que a referida despesa é referente ao caixa, não estando vinculada ao cartão de crédito. Inserida no caixa do mês 07 pelo motivo do caixa 06 estar aprovado e fechado. Não sendo possível inserir DEMANDA EMEEGENCIAL DE FURTO NA AGENCIA | P20: CEF SP SUL | Q20: Saque VExpenses | R20: REGIONAL SP | S20: 1 | W20: 0 | X20: BRL | Y20: 690 | AB20: 690 | AC20: Sim
A21: =YEAR(F21) -> 2026 | B21: =UPPER(TEXT(F21,"MMMM")) -> MARÇO | C21: 81660359 | D21: 10906730 | E21: CAIXA 07/2026 | F21: 46111 | G21: BEATRIZ SILVA DE SIQUEIRA | H21: 35575473880 | I21: Aberto | K21: Recibo | L21: MATERIAL | M21: Não | N21: Identificadas notas desvinculadas do caixa no período de 03/2026, desvinculados sem apresentação de justificativa. Caixa de 03/26 já fechado impossibilitado vinculação no mesmo no caixa | P21: CEF SP SUL | Q21: Saque VExpenses | R21: REGIONAL SP | S21: 1 | W21: 0 | X21: BRL | Y21: 139.98 | AB21: 139.98 | AC21: Não
A22: =YEAR(F22) -> 2026 | B22: =UPPER(TEXT(F22,"MMMM")) -> MARÇO | C22: 81659592 | D22: 10906730 | E22: CAIXA 07/2026 | F22: 46102 | G22: BEATRIZ SILVA DE SIQUEIRA | H22: 35575473880 | I22: Aberto | K22: Material | L22: MATERIAL | M22: Não | N22: Identificadas notas desvinculadas do caixa no período de 03/2026, sem apresentação de justificativa. . Caixa de 03/26 já fechado impossibilitado vinculação no mesmo no caixa correto | P22: CEF SP SUL | Q22: Saque VExpenses | R22: REGIONAL SP | S22: 1 | W22: 0 | X22: BRL | Y22: 27.39 | AB22: 27.39 | AC22: Não
A23: =YEAR(F23) -> 2026 | B23: =UPPER(TEXT(F23,"MMMM")) -> JUNHO | C23: 85799387 | D23: 10657027 | E23: CAIXA 06/2026 | F23: 46203 | G23: BEATRIZ SILVA DE SIQUEIRA | H23: 35575473880 | I23: Aprovado | K23: Material | L23: MATERIAL | M23: Não | N23: Atendimento de chamado caixa economica | P23: CEF SP SUL | Q23: Saque VExpenses | R23: REGIONAL SP | S23: 1 | X23: BRL | Y23: 125 | AB23: 125 | AC23: Não
A24: =YEAR(F24) -> 2026 | B24: =UPPER(TEXT(F24,"MMMM")) -> JUNHO | C24: 85718404 | D24: 10657027 | E24: CAIXA 06/2026 | F24: 46203 | G24: BEATRIZ SILVA DE SIQUEIRA | H24: 35575473880 | I24: Aprovado | K24: Material | L24: MATERIAL | M24: Não | N24: Atendimento de chamado caixa economica | P24: CEF SP SUL | Q24: Saque VExpenses | R24: REGIONAL SP | S24: 1 | X24: BRL | Y24: 14.99 | AB24: 14.99 | AC24: Não
A25: =YEAR(F25) -> 2026 | B25: =UPPER(TEXT(F25,"MMMM")) -> JUNHO | C25: 86057174 | D25: 10657027 | E25: CAIXA 06/2026 | F25: 46202 | G25: BEATRIZ SILVA DE SIQUEIRA | H25: 35575473880 | I25: Aprovado | K25: Nota 2 | L25: ESTACIONAMENTO | M25: Não | N25: Nota 2 | P25: CEF SP SUL | Q25: Tarifa de Saque | R25: REGIONAL SP | S25: 1 | X25: BRL | Y25: 8 | AB25: 8 | AC25: Não
A26: =YEAR(F26) -> 2026 | B26: =UPPER(TEXT(F26,"MMMM")) -> JUNHO | C26: 85799326 | D26: 10657027 | E26: CAIXA 06/2026 | F26: 46202 | G26: BEATRIZ SILVA DE SIQUEIRA | H26: 35575473880 | I26: Aprovado | K26: Material | L26: MATERIAL | M26: Não | N26: Atendimento de chamado caixa economica | P26: CEF SP SUL | Q26: Saque VExpenses | R26: REGIONAL SP | S26: 1 | X26: BRL | Y26: 69 | AB26: 69 | AC26: Não
A27: =YEAR(F27) -> 2026 | B27: =UPPER(TEXT(F27,"MMMM")) -> JUNHO | C27: 86056975 | D27: 10657027 | E27: CAIXA 06/2026 | F27: 46201 | G27: BEATRIZ SILVA DE SIQUEIRA | H27: 35575473880 | I27: Aprovado | K27: Nota 03 | L27: MATERIAL | M27: Não | N27: Nota 3 | P27: CEF SP SUL | Q27: Tarifa de Saque | R27: REGIONAL SP | S27: 1 | X27: BRL | Y27: 23.4 | AB27: 23.4 | AC27: Não
A28: =YEAR(F28) -> 2026 | B28: =UPPER(TEXT(F28,"MMMM")) -> JUNHO | C28: 86056713 | D28: 10657027 | E28: CAIXA 06/2026 | F28: 46199 | G28: BEATRIZ SILVA DE SIQUEIRA | H28: 35575473880 | I28: Aprovado | K28: Nota 1 | L28: MATERIAL | M28: Não | N28: Nota | P28: CEF SP SUL | Q28: Tarifa de Saque | R28: REGIONAL SP | S28: 1 | X28: BRL | Y28: 42.66 | AB28: 42.66 | AC28: Não
A29: =YEAR(F29) -> 2026 | B29: =UPPER(TEXT(F29,"MMMM")) -> JUNHO | C29: 85799448 | D29: 10657027 | E29: CAIXA 06/2026 | F29: 46198 | G29: BEATRIZ SILVA DE SIQUEIRA | H29: 35575473880 | I29: Aprovado | K29: Material | L29: MATERIAL | M29: Não | N29: Atendimento de chamado caixa economica | P29: CEF SP SUL | Q29: Saque VExpenses | R29: REGIONAL SP | S29: 1 | X29: BRL | Y29: 14.4 | AB29: 14.4 | AC29: Não
A30: =YEAR(F30) -> 2026 | B30: =UPPER(TEXT(F30,"MMMM")) -> JUNHO | C30: 85799274 | D30: 10657027 | E30: CAIXA 06/2026 | F30: 46195 | G30: BEATRIZ SILVA DE SIQUEIRA | H30: 35575473880 | I30: Aprovado | K30: Material | L30: MATERIAL | M30: Não | N30: Atendimento de chamado caixa economica | P30: CEF SP SUL | Q30: Saque VExpenses | R30: REGIONAL SP | S30: 1 | X30: BRL | Y30: 49.9 | AB30: 49.9 | AC30: Não
A31: =YEAR(F31) -> 2026 | B31: =UPPER(TEXT(F31,"MMMM")) -> JUNHO | C31: 85325892 | D31: 10657027 | E31: CAIXA 06/2026 | F31: 46190 | G31: BEATRIZ SILVA DE SIQUEIRA | H31: 35575473880 | I31: Aprovado | K31: Material | L31: MATERIAL | M31: Não | N31: Atendimento de chamado caixa economica | P31: CEF SP SUL | Q31: Saque VExpenses | R31: REGIONAL SP | S31: 1 | X31: BRL | Y31: 39 | AB31: 39 | AC31: Não
A32: =YEAR(F32) -> 2026 | B32: =UPPER(TEXT(F32,"MMMM")) -> JUNHO | C32: 85325789 | D32: 10657027 | E32: CAIXA 06/2026 | F32: 46183 | G32: BEATRIZ SILVA DE SIQUEIRA | H32: 35575473880 | I32: Aprovado | K32: Material | L32: MATERIAL | M32: Não | N32: Atendimento de chamado caixa economica | P32: CEF SP SUL | Q32: Saque VExpenses | R32: REGIONAL SP | S32: 1 | X32: BRL | Y32: 36 | AB32: 36 | AC32: Não
A33: =YEAR(F33) -> 2026 | B33: =UPPER(TEXT(F33,"MMMM")) -> JUNHO | C33: 84256192 | D33: 10657027 | E33: CAIXA 06/2026 | F33: 46182 | G33: BEATRIZ SILVA DE SIQUEIRA | H33: 35575473880 | I33: Aprovado | K33: Material | L33: MATERIAL | M33: Não | N33: AtendImento de chamado caixa economica | P33: CEF SP SUL | Q33: Saque VExpenses | R33: REGIONAL SP | S33: 1 | X33: BRL | Y33: 75.94 | AB33: 75.94 | AC33: Não
A34: =YEAR(F34) -> 2026 | B34: =UPPER(TEXT(F34,"MMMM")) -> JUNHO | C34: 85342217 | D34: 10657027 | E34: CAIXA 06/2026 | F34: 46174 | G34: BEATRIZ SILVA DE SIQUEIRA | H34: 35575473880 | I34: Aprovado | K34: Estacionamento e Pedagio | L34: ESTACIONAMENTO | M34: Não | N34: Atendimento de chamado caixa economica | P34: CEF SP SUL | Q34: Saque VExpenses | R34: REGIONAL SP | S34: 1 | X34: BRL | Y34: 217.3 | AB34: 217.3 | AC34: Não
... A58: =YEAR(F58) -> 2026 | B58: =UPPER(TEXT(F58,"MMMM")) -> ABRIL | C58: 81660193 | D58: 10306286 | E58: CAIXA 04/2026 | F58: 46130 | G58: BEATRIZ SILVA DE SIQUEIRA | H58: 35575473880 | I58: Aprovado | K58: Recibo | L58: MATERIAL | M58: Não | N58: Atendimento de chamado caixa econômica | P58: CEF SP SUL | Q58: Saque VExpenses | R58: REGIONAL SP | S58: 1 | X58: BRL | Y58: 9.8 | AB58: 9.8 | AC58: Não
A59: =YEAR(F59) -> 2026 | B59: =UPPER(TEXT(F59,"MMMM")) -> ABRIL | C59: 81660593 | D59: 10306286 | E59: CAIXA 04/2026 | F59: 46128 | G59: BEATRIZ SILVA DE SIQUEIRA | H59: 35575473880 | I59: Aprovado | K59: Recibo | L59: MATERIAL | M59: Não | N59: Atendimento de chamado caixa econômica | P59: CEF SP SUL | Q59: Saque VExpenses | R59: REGIONAL SP | S59: 1 | W59: 0 | X59: BRL | Y59: 37.89 | AB59: 37.89 | AC59: Não
A60: =YEAR(F60) -> 2026 | B60: =UPPER(TEXT(F60,"MMMM")) -> ABRIL | C60: 81659514 | D60: 10306286 | E60: CAIXA 04/2026 | F60: 46128 | G60: BEATRIZ SILVA DE SIQUEIRA | H60: 35575473880 | I60: Aprovado | K60: Recibo | L60: MATERIAL | M60: Não | N60: Atendimento de chamado caixa econômica | P60: CEF SP SUL | Q60: Saque VExpenses | R60: REGIONAL SP | S60: 1 | X60: BRL | Y60: 37.89 | AB60: 37.89 | AC60: Não
A61: =YEAR(F61) -> 2026 | B61: =UPPER(TEXT(F61,"MMMM")) -> ABRIL | C61: 81660479 | D61: 10306286 | E61: CAIXA 04/2026 | F61: 46120 | G61: BEATRIZ SILVA DE SIQUEIRA | H61: 35575473880 | I61: Aprovado | K61: Recibo | L61: MATERIAL | M61: Não | N61: Atendimento de chamado caixa econômica | P61: CEF SP SUL | Q61: Saque VExpenses | R61: REGIONAL SP | S61: 1 | X61: BRL | Y61: 39.5 | AB61: 39.5 | AC61: Não
A62: =YEAR(F62) -> 2026 | B62: =UPPER(TEXT(F62,"MMMM")) -> ABRIL | C62: 81660253 | D62: 10306286 | E62: CAIXA 04/2026 | F62: 46120 | G62: BEATRIZ SILVA DE SIQUEIRA | H62: 35575473880 | I62: Aprovado | K62: Recibo | L62: MATERIAL | M62: Não | N62: Atendimento de chamado caixa econômica | P62: CEF SP SUL | Q62: Saque VExpenses | R62: REGIONAL SP | S62: 1 | X62: BRL | Y62: 10.7 | AB62: 10.7 | AC62: Não
A63: =YEAR(F63) -> 2026 | B63: =UPPER(TEXT(F63,"MMMM")) -> ABRIL | C63: 81666536 | D63: 10306286 | E63: CAIXA 04/2026 | F63: 46114 | G63: BEATRIZ SILVA DE SIQUEIRA | H63: 35575473880 | I63: Aprovado | K63: Material | L63: MATERIAL | M63: Não | N63: Atendimento de chamado caixa econômica | P63: CEF SP SUL | Q63: Saque VExpenses | R63: REGIONAL SP | S63: 1 | X63: BRL | Y63: 44.6 | AB63: 44.6 | AC63: Não
A64: =YEAR(F64) -> 2026 | B64: =UPPER(TEXT(F64,"MMMM")) -> ABRIL | C64: 81660043 | D64: 10306286 | E64: CAIXA 04/2026 | F64: 46114 | G64: BEATRIZ SILVA DE SIQUEIRA | H64: 35575473880 | I64: Aprovado | K64: Recibo | L64: MATERIAL | M64: Não | N64: Atendimento de chamado caixa econômica | P64: CEF SP SUL | Q64: Saque VExpenses | R64: REGIONAL SP | S64: 1 | X64: BRL | Y64: 88.9 | AB64: 88.9 | AC64: Não
A65: =YEAR(F65) -> 2026 | B65: =UPPER(TEXT(F65,"MMMM")) -> ABRIL | C65: 81783947 | D65: 10306286 | E65: CAIXA 04/2026 | F65: 46113 | G65: BEATRIZ SILVA DE SIQUEIRA | H65: 35575473880 | I65: Aprovado | K65: Recibo | L65: MATERIAL | M65: Não | N65: Atendimento de chamado caixa economica | P65: CEF SP SUL | Q65: Saque VExpenses | R65: REGIONAL SP | S65: 1 | X65: BRL | Y65: 173 | AB65: 173 | AC65: Não
A66: =YEAR(F66) -> 2026 | B66: =UPPER(TEXT(F66,"MMMM")) -> ABRIL | C66: 81680496 | D66: 10306286 | E66: CAIXA 04/2026 | F66: 46113 | G66: BEATRIZ SILVA DE SIQUEIRA | H66: 35575473880 | I66: Aprovado | K66: Estacionamento e Pedagio | L66: PEDAGIO | M66: Não | N66: Atendimento de chamado caixa economica | P66: CEF SP SUL | Q66: Saque VExpenses | R66: REGIONAL SP | S66: 1 | X66: BRL | Y66: 593.45 | AB66: 593.45 | AC66: Não
A67: =YEAR(F67) -> 2026 | B67: =UPPER(TEXT(F67,"MMMM")) -> ABRIL | C67: 81666645 | D67: 10306286 | E67: CAIXA 04/2026 | F67: 46113 | G67: BEATRIZ SILVA DE SIQUEIRA | H67: 35575473880 | I67: Aprovado | K67: Recibo | L67: MATERIAL | M67: Não | N67: Atendimento de chamado caixa econômica | P67: CEF SP SUL | Q67: Saque VExpenses | R67: REGIONAL SP | S67: 1 | X67: BRL | Y67: 128.9 | AB67: 128.9 | AC67: Não
A68: =YEAR(F68) -> 2026 | B68: =UPPER(TEXT(F68,"MMMM")) -> ABRIL | C68: 81659718 | D68: 10306286 | E68: CAIXA 04/2026 | F68: 46113 | G68: BEATRIZ SILVA DE SIQUEIRA | H68: 35575473880 | I68: Aprovado | K68: Recibo | L68: MATERIAL | M68: Não | N68: Atendimento de chamado caixa econômica | P68: CEF SP SUL | Q68: Saque VExpenses | R68: REGIONAL SP | S68: 1 | X68: BRL | Y68: 128.9 | AB68: 128.9 | AC68: Não
...

Sheet EXTRATO
A1: ANO | B1: MÊS | C1: Data | D1: Hora | E1: Código de Transação | F1: Usuário | G1: Tipo | H1: Descrição | I1: Valor | K1: Soma de Valor | L1: Rótulos de Coluna
A2: =YEAR(C2) -> 2025 | B2: =UPPER(TEXT(C2,"MMMM")) -> MAIO | C2: 45805.443 | D2: 10:37:53 | E2: 3B2E367253EF8CA8E83B7A5A0A5FA3EA | F2: Beatriz Silva de Siqueira | G2: Carga | H2: Transf. EQS > Beatriz S. d. Siqueira: 2 QUINZENA - MAIO/2025 | I2: 1183.02 | K2: Rótulos de Linha | L2: Carga | M2: Saque | N2: Taxa | O2: Transferência | P2: Total Geral
A3: =YEAR(C3) -> 2025 | B3: =UPPER(TEXT(C3,"MMMM")) -> JUNHO | C3: 45819.749 | D3: 17:57:52 | E3: 6CC895AB9D844418520C750FC20F1192 | F3: Beatriz Silva de Siqueira | G3: Carga | H3: Transf. EQS > Beatriz S. d. Siqueira | I3: 16.98 | K3: 2025 | L3: 14777.43 | M3: -14640 | N3: -126 | P3: 11.43
A4: =YEAR(C4) -> 2025 | B4: =UPPER(TEXT(C4,"MMMM")) -> JUNHO | C4: 45824.754 | D4: 18:05:58 | E4: 3C9F00EDCE014FBD8D62E371A1889A16 | F4: Beatriz Silva de Siqueira | G4: Saque | H4: TECBAN-MOOCA PLAZA SHO | I4: -1000 | K4: mai | L4: 1183.02 | P4: 1183.02
A5: =YEAR(C5) -> 2025 | B5: =UPPER(TEXT(C5,"MMMM")) -> JUNHO | C5: 45824.755 | D5: 18:06:56 | E5: 5446F8D96F787419D3864F73C9DF89CB | F5: Beatriz Silva de Siqueira | G5: Saque | H5: TECBAN-MOOCA PLAZA SHO | I5: -180 | K5: jun | L5: 1210.98 | M5: -2180 | N5: -21 | P5: -990.02
A6: =YEAR(C6) -> 2025 | B6: =UPPER(TEXT(C6,"MMMM")) -> JUNHO | C6: 45824.764 | D6: 18:20:25 | E6: 625B05FFFEA456DEA35C7C79E56DE386 | F6: Beatriz Silva de Siqueira | G6: Taxa | H6: Taxa de saque | I6: -7 | K6: jul | L6: 2953.46 | M6: -3100 | N6: -28 | P6: -174.54
A7: =YEAR(C7) -> 2025 | B7: =UPPER(TEXT(C7,"MMMM")) -> JUNHO | C7: 45824.764 | D7: 18:20:37 | E7: 71BC5C5D6727F3D25B3F1ED2B57011BB | F7: Beatriz Silva de Siqueira | G7: Taxa | H7: Taxa de saque | I7: -7 | K7: set | L7: 4195.54 | M7: -4000 | N7: -28 | P7: 167.54
A8: =YEAR(C8) -> 2025 | B8: =UPPER(TEXT(C8,"MMMM")) -> JUNHO | C8: 45833.707 | D8: 16:57:30 | E8: 0AAB4CEC1E1640E0EC2962B907DE6EC9 | F8: Beatriz Silva de Siqueira | G8: Carga | H8: Transf. EQS > Beatriz S. d. Siqueira | I8: 1194 | K8: out | L8: 2957.62 | M8: -3110 | N8: -28 | P8: -180.38
A9: =YEAR(C9) -> 2025 | B9: =UPPER(TEXT(C9,"MMMM")) -> JUNHO | C9: 45834.73 | D9: 17:30:34 | E9: F7EEC84E9CFE8F5856FC9F4367FA9B72 | F9: Beatriz Silva de Siqueira | G9: Saque | H9: TECBAN-MOOCA PLAZA SHO | I9: -1000 | K9: nov | L9: 688.07 | M9: -680 | N9: -7 | P9: 1.07
A10: =YEAR(C10) -> 2025 | B10: =UPPER(TEXT(C10,"MMMM")) -> JUNHO | C10: 45834.758 | D10: 18:11:16 | E10: A7D4C6FB4F0F0F497BA8262E922B302C | F10: Beatriz Silva de Siqueira | G10: Taxa | H10: Taxa de saque | I10: -7 | K10: dez | L10: 1588.74 | M10: -1570 | N10: -14 | P10: 4.74
A11: =YEAR(C11) -> 2025 | B11: =UPPER(TEXT(C11,"MMMM")) -> JULHO | C11: 45849.66 | D11: 15:49:54 | E11: D4A808FA2449A8946B3F309D124CDD05 | F11: Beatriz Silva de Siqueira | G11: Carga | H11: Transf. EQS > Beatriz S. d. Siqueira | I11: 1026.01 | K11: 2026 | L11: 12914 | M11: -12790 | N11: -126 | O11: -6.43 | P11: -8.43
A12: =YEAR(C12) -> 2025 | B12: =UPPER(TEXT(C12,"MMMM")) -> JULHO | C12: 45849.706 | D12: 16:56:09 | E12: 464BAD8451A9F8050B92FB44450257E8 | F12: Beatriz Silva de Siqueira | G12: Saque | H12: TECBAN-AP NOVO BRILHOA | I12: -1000 | K12: jan | L12: 4306 | M12: -4090 | N12: -35 | O12: -6.43 | P12: 174.57
A13: =YEAR(C13) -> 2025 | B13: =UPPER(TEXT(C13,"MMMM")) -> JULHO | C13: 45849.706 | D13: 16:57:14 | E13: 00442BEA4336339D7EFAE2BF1026CEDE | F13: Beatriz Silva de Siqueira | G13: Saque | H13: TECBAN-AP NOVO BRILHOA | I13: -200 | K13: fev | L13: 2013.46 | M13: -2170 | N13: -21 | P13: -177.54
A14: =YEAR(C14) -> 2025 | B14: =UPPER(TEXT(C14,"MMMM")) -> JULHO | C14: 45849.715 | D14: 17:09:53 | E14: 8FBCD955A516D74EB813F05AD0274A46 | F14: Beatriz Silva de Siqueira | G14: Taxa | H14: Taxa de saque | I14: -7 | K14: mar | L14: 1812.44 | M14: -1800 | N14: -14 | P14: -1.56
A15: =YEAR(C15) -> 2025 | B15: =UPPER(TEXT(C15,"MMMM")) -> JULHO | C15: 45849.716 | D15: 17:10:20 | E15: 97E9E9BE620FE3AFB49771CC1D1DBBEC | F15: Beatriz Silva de Siqueira | G15: Taxa | H15: Taxa de saque | I15: -7 | K15: abr | L15: 1810.16 | M15: -1800 | N15: -14 | P15: -3.84
A16: =YEAR(C16) -> 2025 | B16: =UPPER(TEXT(C16,"MMMM")) -> JULHO | C16: 45863.666 | D16: 15:59:27 | E16: AAB86613620AB63465EA3CBD7A3A03EC | F16: Beatriz Silva de Siqueira | G16: Carga | H16: Transf. EQS > Beatriz S. d. Siqueira | I16: 1927.45 | K16: mai | L16: 1594.15 | M16: -1560 | N16: -28 | P16: 6.15
A17: =YEAR(C17) -> 2025 | B17: =UPPER(TEXT(C17,"MMMM")) -> JULHO | C17: 45869.496 | D17: 11:53:39 | E17: 18374CA515DC33AE05550F9BF9B389C6 | F17: Beatriz Silva de Siqueira | G17: Saque | H17: TECBAN-SONDA CARRAO II | I17: -1000 | K17: jun | L17: 391.86 | M17: -380 | N17: -7 | P17: 4.86
A18: =YEAR(C18) -> 2025 | B18: =UPPER(TEXT(C18,"MMMM")) -> JULHO | C18: 45869.496 | D18: 11:54:48 | E18: 2EC89539A2833F8F8C69128B755F1430 | F18: Beatriz Silva de Siqueira | G18: Saque | H18: TECBAN-SONDA CARRAO II | I18: -900 | K18: jul | L18: 985.93 | M18: -990 | N18: -7 | P18: -11.07
A19: =YEAR(C19) -> 2025 | B19: =UPPER(TEXT(C19,"MMMM")) -> JULHO | C19: 45869.501 | D19: 12:02:09 | E19: BBBE6C9431921475F44F05F98E670F69 | F19: Beatriz Silva de Siqueira | G19: Taxa | H19: Taxa de saque | I19: -7 | K19: Total Geral | L19: 27691.43 | M19: -27430 | N19: -252 | O19: -6.43 | P19: 3
A20: =YEAR(C20) -> 2025 | B20: =UPPER(TEXT(C20,"MMMM")) -> JULHO | C20: 45869.502 | D20: 12:02:36 | E20: 8B887FAC7780181AA39797F7C42125C2 | F20: Beatriz Silva de Siqueira | G20: Taxa | H20: Taxa de saque | I20: -7
A21: =YEAR(C21) -> 2025 | B21: =UPPER(TEXT(C21,"MMMM")) -> SETEMBRO | C21: 45911.688 | D21: 16:30:27 | E21: 88B68D4FC8B377BCCFFB314AF617F449 | F21: Beatriz Silva de Siqueira | G21: Carga | H21: Transf. EQS > Beatriz S. d. Siqueira | I21: 2181.54
A22: =YEAR(C22) -> 2025 | B22: =UPPER(TEXT(C22,"MMMM")) -> SETEMBRO | C22: 45913.682 | D22: 16:21:29 | E22: E135C626166E2808F99BA49EFC549822 | F22: Beatriz Silva de Siqueira | G22: Saque | H22: TECBAN-CARREFOUR SCS I | I22: -1000
A23: =YEAR(C23) -> 2025 | B23: =UPPER(TEXT(C23,"MMMM")) -> SETEMBRO | C23: 45913.682 | D23: 16:21:57 | E23: F893E17394162C0198BF1EE7006A0101 | F23: Beatriz Silva de Siqueira | G23: Taxa | H23: Taxa de saque | I23: -7
A24: =YEAR(C24) -> 2025 | B24: =UPPER(TEXT(C24,"MMMM")) -> SETEMBRO | C24: 45913.683 | D24: 16:23:30 | E24: C4365B707920100EE3526ACFE0373A9F | F24: Beatriz Silva de Siqueira | G24: Saque | H24: TECBAN-CARREFOUR SCS I | I24: -1000
A25: =YEAR(C25) -> 2025 | B25: =UPPER(TEXT(C25,"MMMM")) -> SETEMBRO | C25: 45913.683 | D25: 16:23:57 | E25: 341DB4A6711C556245A483D2436CDAC9 | F25: Beatriz Silva de Siqueira | G25: Taxa | H25: Taxa de saque | I25: -7
A26: =YEAR(C26) -> 2025 | B26: =UPPER(TEXT(C26,"MMMM")) -> SETEMBRO | C26: 45925.706 | D26: 16:57:21 | E26: ABC85FAB8B75C6014CD864C095F66C29 | F26: Beatriz Silva de Siqueira | G26: Carga | H26: Transf. EQS > Beatriz S. d. Siqueira | I26: 2014
A27: =YEAR(C27) -> 2025 | B27: =UPPER(TEXT(C27,"MMMM")) -> SETEMBRO | C27: 45925.748 | D27: 17:57:00 | E27: 3622E47A201D701FF773523BC8C4118F | F27: Beatriz Silva de Siqueira | G27: Saque | H27: TECBAN-MOOCA PLAZA SHO | I27: -1000
A28: =YEAR(C28) -> 2025 | B28: =UPPER(TEXT(C28,"MMMM")) -> SETEMBRO | C28: 45925.749 | D28: 17:57:59 | E28: A0C51E12EE3405BB01BBE1EBDA1F2D91 | F28: Beatriz Silva de Siqueira | G28: Saque | H28: TECBAN-MOOCA PLAZA SHO | I28: -1000
A29: =YEAR(C29) -> 2025 | B29: =UPPER(TEXT(C29,"MMMM")) -> SETEMBRO | C29: 45925.75 | D29: 17:59:59 | E29: 9247D0152B6C54B4F9784B15F34C1FB3 | F29: Beatriz Silva de Siqueira | G29: Taxa | H29: Taxa de saque | I29: -7
A30: =YEAR(C30) -> 2025 | B30: =UPPER(TEXT(C30,"MMMM")) -> SETEMBRO | C30: 45925.751 | D30: 18:00:48 | E30: 3176B58A01A077807DBFA8F2E1A95F05 | F30: Beatriz Silva de Siqueira | G30: Taxa | H30: Taxa de saque | I30: -7
A31: =YEAR(C31) -> 2025 | B31: =UPPER(TEXT(C31,"MMMM")) -> OUTUBRO | C31: 45943.7 | D31: 16:48:42 | E31: 3A1EBC8703A72CFB1FA11D5794365B17 | F31: Beatriz Silva de Siqueira | G31: Carga | H31: Transf. EQS > Beatriz S. d. Siqueira | I31: 1471.81
... A98: =YEAR(C98) -> 2026 | B98: =UPPER(TEXT(C98,"MMMM")) -> JULHO | C98: 46218.634 | D98: 15:12:58 | E98: 81E0ED60717A7B7827C572A99E532C61 | F98: Beatriz Silva de Siqueira | G98: Taxa | H98: Taxa de saque | I98: -7
