Workbook
Name SegmentaçãodeDados_GESTOR: #N/A

Sheet 1 QZ VEXPENSES 04_2026
I5: =SUBTOTAL(9,I7:I1048576) -> -55059.77 | J5: =SUBTOTAL(9,J7:J1048576) -> 292255.22 | K5: =SUBTOTAL(9,K7:K1048576) -> 455630 | L5: =SUBTOTAL(9,L7:L1048576) -> 75298.19 | M5: =SUBTOTAL(9,M7:M1048576) -> 0 | N5: =SUBTOTAL(9,N332:N1048576) -> -492.85 | O5: =SUBTOTAL(9,O7:O1048576) -> 19919 | P5: =SUBTOTAL(9,P7:P1048576) -> 225885.72
B6: PORTADOR | C6: CPF | D6: STATUS COLAB | E6: CENTRO CUSTO | F6: COD CENTRO CUSTO | G6: GESTOR | H6: DIREÇÃO | I6: SALDO REEMBOLSAR | J6: SALDO FINAL | K6: 1QZ DE ABRIL 26 | L6: SALDO CARTAO | M6: ADIANTAMENTO | N6: CARGA PARCIAL | O6: REEMBOLSO | P6: CARGA FINAL | Q6: STATUS DO CARTAO | R6: OBS
B7: RAFAEL AMORIM VELLO | C7: 01677920599 | D7: =_xlfn.XLOOKUP(Tabela1[[#This Row],[CPF]],[1]Funcionário!$B:$B,[1]Funcionário!$H:$H) -> ATIVO | E7: CEF NORTE OESTE BA | G7: GERSON OLIVEIRA | H7: ROGERIO SCATAMBULO | J7: 291.66 | K7: 16000 | L7: 20 | N7: =Tabela1[[#This Row],[1QZ DE ABRIL 26]]-Tabela1[[#This Row],[SALDO FINAL]]-Tabela1[[#This Row],[SALDO CARTAO]]-Tabela1[[#This Row],[ADIANTAMENTO]] -> 15688.34 | O7: 0 | P7: =IF(Tabela1[[#This Row],[CARGA PARCIAL]]<0,0,Tabela1[[#This Row],[CARGA PARCIAL]])+Tabela1[[#This Row],[REEMBOLSO]] -> 15688.34 | Q7: Cartão ativo
B8: ABNER ANDRADE CAVALCANTE | C8: 02027745203 | D8: =_xlfn.XLOOKUP(Tabela1[[#This Row],[CPF]],[1]Funcionário!$B:$B,[1]Funcionário!$H:$H) -> ATIVO | E8: CEF AM AC RR | G8: ANGELICA SOARES | H8: ROGERIO SCATAMBULO | I8: -98.92 | J8: 0 | K8: 9840 | L8: 5 | N8: =Tabela1[[#This Row],[1QZ DE ABRIL 26]]-Tabela1[[#This Row],[SALDO FINAL]]-Tabela1[[#This Row],[SALDO CARTAO]]-Tabela1[[#This Row],[ADIANTAMENTO]] -> 9835 | O8: 0 | P8: =IF(Tabela1[[#This Row],[CARGA PARCIAL]]<0,0,Tabela1[[#This Row],[CARGA PARCIAL]])+Tabela1[[#This Row],[REEMBOLSO]] -> 9835 | Q8: Cartão ativo
B9: ANDRE ARANHA MEISTER | C9: 03032275326 | D9: =_xlfn.XLOOKUP(Tabela1[[#This Row],[CPF]],[1]Funcionário!$B:$B,[1]Funcionário!$H:$H) -> ATIVO | E9: BB MARANHAO MA | G9: ANGELICA SOARES | H9: ROGERIO SCATAMBULO | J9: 18329.5 | K9: 9000 | L9: 1154.94 | N9: =Tabela1[[#This Row],[1QZ DE ABRIL 26]]-Tabela1[[#This Row],[SALDO FINAL]]-Tabela1[[#This Row],[SALDO CARTAO]]-Tabela1[[#This Row],[ADIANTAMENTO]] -> -10484.44 | O9: 0 | P9: =IF(Tabela1[[#This Row],[CARGA PARCIAL]]<0,0,Tabela1[[#This Row],[CARGA PARCIAL]])+Tabela1[[#This Row],[REEMBOLSO]] -> 0 | Q9: Cartão ativo
B10: JAEDER RODRIGUES JUNIOR | C10: 07505987607 | D10: =_xlfn.XLOOKUP(Tabela1[[#This Row],[CPF]],[1]Funcionário!$B:$B,[1]Funcionário!$H:$H) -> ATIVO | E10: CEF NORDESTE MG | G10: HUGO ALEXANDRE | H10: MARCOS CARIAS | J10: 1614.44 | K10: 7000 | L10: 2 | N10: =Tabela1[[#This Row],[1QZ DE ABRIL 26]]-Tabela1[[#This Row],[SALDO FINAL]]-Tabela1[[#This Row],[SALDO CARTAO]]-Tabela1[[#This Row],[ADIANTAMENTO]] -> 5383.56 | O10: 0 | P10: =IF(Tabela1[[#This Row],[CARGA PARCIAL]]<0,0,Tabela1[[#This Row],[CARGA PARCIAL]])+Tabela1[[#This Row],[REEMBOLSO]] -> 5383.56 | Q10: Cartão ativo
B11: JUSTINO NOGUEIRA PEIXOTO JUNIOR | C11: 09246793790 | D11: =_xlfn.XLOOKUP(Tabela1[[#This Row],[CPF]],[1]Funcionário!$B:$B,[1]Funcionário!$H:$H) -> ATIVO | E11: PTB EDISE RJ | G11: ALLAN JEFFERSON | H11: ROGERIO SCATAMBULO | I11: -428.82 | J11: 0 | K11: 7000 | L11: 7000 | N11: =Tabela1[[#This Row],[1QZ DE ABRIL 26]]-Tabela1[[#This Row],[SALDO FINAL]]-Tabela1[[#This Row],[SALDO CARTAO]]-Tabela1[[#This Row],[ADIANTAMENTO]] -> 0 | O11: 0 | P11: =IF(Tabela1[[#This Row],[CARGA PARCIAL]]<0,0,Tabela1[[#This Row],[CARGA PARCIAL]])+Tabela1[[#This Row],[REEMBOLSO]] -> 0 | Q11: Cartão ativo
B12: EDSON VEIGA SILVEIRA | C12: 62063774072 | D12: =_xlfn.XLOOKUP(Tabela1[[#This Row],[CPF]],[1]Funcionário!$B:$B,[1]Funcionário!$H:$H) -> ATIVO | E12: CLARO CO | G12: ANGELICA SOARES | H12: ROGERIO SCATAMBULO | J12: 226.65 | K12: 6800 | L12: 4635.66 | N12: =Tabela1[[#This Row],[1QZ DE ABRIL 26]]-Tabela1[[#This Row],[SALDO FINAL]]-Tabela1[[#This Row],[SALDO CARTAO]]-Tabela1[[#This Row],[ADIANTAMENTO]] -> 1937.69 | O12: 0 | P12: =IF(Tabela1[[#This Row],[CARGA PARCIAL]]<0,0,Tabela1[[#This Row],[CARGA PARCIAL]])+Tabela1[[#This Row],[REEMBOLSO]] -> 1937.69 | Q12: Cartão ativo
B13: LUDGERO HORACIO DE OLIVEIRA | C13: 06576198922 | D13: =_xlfn.XLOOKUP(Tabela1[[#This Row],[CPF]],[1]Funcionário!$B:$B,[1]Funcionário!$H:$H) -> ATIVO | E13: CEF NORTE PR | G13: LEANDRO MARCUSSO | H13: EVERSON GAIDSTIECHI | J13: 3693.1 | K13: 6500 | L13: 981.69 | N13: =Tabela1[[#This Row],[1QZ DE ABRIL 26]]-Tabela1[[#This Row],[SALDO FINAL]]-Tabela1[[#This Row],[SALDO CARTAO]]-Tabela1[[#This Row],[ADIANTAMENTO]] -> 1825.21 | O13: 0 | P13: =IF(Tabela1[[#This Row],[CARGA PARCIAL]]<0,0,Tabela1[[#This Row],[CARGA PARCIAL]])+Tabela1[[#This Row],[REEMBOLSO]] -> 1825.21 | Q13: Cartão ativo
B14: BRUNO OLIVEIRA DIAS | C14: 11992259755 | D14: =_xlfn.XLOOKUP(Tabela1[[#This Row],[CPF]],[1]Funcionário!$B:$B,[1]Funcionário!$H:$H) -> ATIVO | E14: PTB TIC INFRA | G14: VINICIUS LOCATELLY | H14: MARCOS CARIAS | J14: 4637.6 | K14: 6200 | L14: 4283.83 | N14: =Tabela1[[#This Row],[1QZ DE ABRIL 26]]-Tabela1[[#This Row],[SALDO FINAL]]-Tabela1[[#This Row],[SALDO CARTAO]]-Tabela1[[#This Row],[ADIANTAMENTO]] -> -2721.43 | O14: 0 | P14: =IF(Tabela1[[#This Row],[CARGA PARCIAL]]<0,0,Tabela1[[#This Row],[CARGA PARCIAL]])+Tabela1[[#This Row],[REEMBOLSO]] -> 0 | Q14: Cartão ativo
B15: JOSE CARLOS BATISTA | C15: 26652452804 | D15: =_xlfn.XLOOKUP(Tabela1[[#This Row],[CPF]],[1]Funcionário!$B:$B,[1]Funcionário!$H:$H) -> ATIVO | E15: PTB INFRA SUDESTE | G15: LEANDRO NUNES | H15: EVERSON GAIDSTIECHI | J15: 1674.27 | K15: 6000 | L15: 58 | N15: =Tabela1[[#This Row],[1QZ DE ABRIL 26]]-Tabela1[[#This Row],[SALDO FINAL]]-Tabela1[[#This Row],[SALDO CARTAO]]-Tabela1[[#This Row],[ADIANTAMENTO]] -> 4267.73 | O15: 0 | P15: =IF(Tabela1[[#This Row],[CARGA PARCIAL]]<0,0,Tabela1[[#This Row],[CARGA PARCIAL]])+Tabela1[[#This Row],[REEMBOLSO]] -> 4267.73 | Q15: Cartão ativo
B16: LUCAS MARTINS MACAN | C16: 00975748998 | D16: =_xlfn.XLOOKUP(Tabela1[[#This Row],[CPF]],[1]Funcionário!$B:$B,[1]Funcionário!$H:$H) -> ATIVO | E16: CEF CEARA | G16: GERSON OLIVEIRA | H16: ROGERIO SCATAMBULO | J16: 1784.53 | K16: 6000 | L16: 4.06 | N16: =Tabela1[[#This Row],[1QZ DE ABRIL 26]]-Tabela1[[#This Row],[SALDO FINAL]]-Tabela1[[#This Row],[SALDO CARTAO]]-Tabela1[[#This Row],[ADIANTAMENTO]] -> 4211.41 | O16: 0 | P16: =IF(Tabela1[[#This Row],[CARGA PARCIAL]]<0,0,Tabela1[[#This Row],[CARGA PARCIAL]])+Tabela1[[#This Row],[REEMBOLSO]] -> 4211.41 | Q16: Cartão ativo
B17: SAULO ARAUJO DE PAULA | C17: 31040091806 | D17: =_xlfn.XLOOKUP(Tabela1[[#This Row],[CPF]],[1]Funcionário!$B:$B,[1]Funcionário!$H:$H) -> ATIVO | E17: CEF SP SUL | G17: LEANDRO NUNES | H17: EVERSON GAIDSTIECHI | J17: 3099.95 | K17: 5750 | L17: 62.3 | N17: =Tabela1[[#This Row],[1QZ DE ABRIL 26]]-Tabela1[[#This Row],[SALDO FINAL]]-Tabela1[[#This Row],[SALDO CARTAO]]-Tabela1[[#This Row],[ADIANTAMENTO]] -> 2587.75 | O17: 12084 | P17: =IF(Tabela1[[#This Row],[CARGA PARCIAL]]<0,0,Tabela1[[#This Row],[CARGA PARCIAL]])+Tabela1[[#This Row],[REEMBOLSO]] -> 14671.75 | Q17: Cartão ativo
B18: FLAVIO FERNANDES DOS REIS LIMA | C18: 01767960107 | D18: =_xlfn.XLOOKUP(Tabela1[[#This Row],[CPF]],[1]Funcionário!$B:$B,[1]Funcionário!$H:$H) -> ATIVO | E18: TELEFONICA CO | G18: ANGELICA SOARES | H18: ROGERIO SCATAMBULO | J18: 7169.96 | K18: 5700 | L18: 284.08 | N18: =Tabela1[[#This Row],[1QZ DE ABRIL 26]]-Tabela1[[#This Row],[SALDO FINAL]]-Tabela1[[#This Row],[SALDO CARTAO]]-Tabela1[[#This Row],[ADIANTAMENTO]] -> -1754.04 | O18: 0 | P18: =IF(Tabela1[[#This Row],[CARGA PARCIAL]]<0,0,Tabela1[[#This Row],[CARGA PARCIAL]])+Tabela1[[#This Row],[REEMBOLSO]] -> 0 | Q18: Cartão ativo
B19: WALTER DE CAMPOS NUNES NETO | C19: 99114160030 | D19: =_xlfn.XLOOKUP(Tabela1[[#This Row],[CPF]],[1]Funcionário!$B:$B,[1]Funcionário!$H:$H) -> ATIVO | E19: CLARO INFRA RS | G19: BRUNO EDUARDO | H19: EVERSON GAIDSTIECHI | I19: -324.54 | J19: 0 | K19: 5600 | L19: 317.49 | N19: =Tabela1[[#This Row],[1QZ DE ABRIL 26]]-Tabela1[[#This Row],[SALDO FINAL]]-Tabela1[[#This Row],[SALDO CARTAO]]-Tabela1[[#This Row],[ADIANTAMENTO]] -> 5282.51 | O19: 0 | P19: =IF(Tabela1[[#This Row],[CARGA PARCIAL]]<0,0,Tabela1[[#This Row],[CARGA PARCIAL]])+Tabela1[[#This Row],[REEMBOLSO]] -> 5282.51 | Q19: Cartão ativo
B20: ANTONIO FERREIRA DE MENDONCA NETO | C20: 05766838760 | D20: =_xlfn.XLOOKUP(Tabela1[[#This Row],[CPF]],[1]Funcionário!$B:$B,[1]Funcionário!$H:$H) -> ATIVO | E20: TRIBUNAL DE JUSTICA RJ | G20: ALLAN JEFFERSON | H20: ROGERIO SCATAMBULO | J20: 3904.24 | K20: 5000 | L20: 695.1 | N20: =Tabela1[[#This Row],[1QZ DE ABRIL 26]]-Tabela1[[#This Row],[SALDO FINAL]]-Tabela1[[#This Row],[SALDO CARTAO]]-Tabela1[[#This Row],[ADIANTAMENTO]] -> 400.66 | O20: 0 | P20: =IF(Tabela1[[#This Row],[CARGA PARCIAL]]<0,0,Tabela1[[#This Row],[CARGA PARCIAL]])+Tabela1[[#This Row],[REEMBOLSO]] -> 400.66 | Q20: Cartão ativo
B21: BRUNO FERREIRA DE SOUZA RODRIGUES | C21: 16306431730 | D21: =_xlfn.XLOOKUP(Tabela1[[#This Row],[CPF]],[1]Funcionário!$B:$B,[1]Funcionário!$H:$H) -> ATIVO | E21: TELEFONICA RJ | G21: ALLAN JEFFERSON | H21: ROGERIO SCATAMBULO | I21: -31.87 | J21: 0 | K21: 5000 | L21: 5 | N21: =Tabela1[[#This Row],[1QZ DE ABRIL 26]]-Tabela1[[#This Row],[SALDO FINAL]]-Tabela1[[#This Row],[SALDO CARTAO]]-Tabela1[[#This Row],[ADIANTAMENTO]] -> 4995 | O21: 0 | P21: =IF(Tabela1[[#This Row],[CARGA PARCIAL]]<0,0,Tabela1[[#This Row],[CARGA PARCIAL]])+Tabela1[[#This Row],[REEMBOLSO]] -> 4995 | Q21: Cartão ativo
B22: JOELSON FERREIRA DOS SANTOS | C22: 07690263623 | D22: =_xlfn.XLOOKUP(Tabela1[[#This Row],[CPF]],[1]Funcionário!$B:$B,[1]Funcionário!$H:$H) -> ATIVO | E22: CEF SUDESTE MG | G22: HUGO ALEXANDRE | H22: MARCOS CARIAS | J22: 5903.25 | K22: 5000 | L22: 57.18 | N22: =Tabela1[[#This Row],[1QZ DE ABRIL 26]]-Tabela1[[#This Row],[SALDO FINAL]]-Tabela1[[#This Row],[SALDO CARTAO]]-Tabela1[[#This Row],[ADIANTAMENTO]] -> -960.43 | O22: 0 | P22: =IF(Tabela1[[#This Row],[CARGA PARCIAL]]<0,0,Tabela1[[#This Row],[CARGA PARCIAL]])+Tabela1[[#This Row],[REEMBOLSO]] -> 0 | Q22: Cartão ativo
B23: MARCO AURELIO DE ANDRADE MORAES | C23: 72756284220 | D23: =_xlfn.XLOOKUP(Tabela1[[#This Row],[CPF]],[1]Funcionário!$B:$B,[1]Funcionário!$H:$H) -> ATIVO | E23: CEF AM AC RR | G23: ANGELICA SOARES | H23: ROGERIO SCATAMBULO | J23: 2658.66 | K23: 5000 | L23: 5 | N23: =Tabela1[[#This Row],[1QZ DE ABRIL 26]]-Tabela1[[#This Row],[SALDO FINAL]]-Tabela1[[#This Row],[SALDO CARTAO]]-Tabela1[[#This Row],[ADIANTAMENTO]] -> 2336.34 | O23: 0 | P23: =IF(Tabela1[[#This Row],[CARGA PARCIAL]]<0,0,Tabela1[[#This Row],[CARGA PARCIAL]])+Tabela1[[#This Row],[REEMBOLSO]] -> 2336.34 | Q23: Cartão ativo
B24: VICTOR SIGOLO PINHEIRO PIMENTA | C24: 12237490619 | D24: =_xlfn.XLOOKUP(Tabela1[[#This Row],[CPF]],[1]Funcionário!$B:$B,[1]Funcionário!$H:$H) -> ATIVO | E24: INSS SP | G24: LEANDRO NUNES | H24: EVERSON GAIDSTIECHI | J24: 3076.02 | K24: 5000 | L24: 20.13 | N24: =Tabela1[[#This Row],[1QZ DE ABRIL 26]]-Tabela1[[#This Row],[SALDO FINAL]]-Tabela1[[#This Row],[SALDO CARTAO]]-Tabela1[[#This Row],[ADIANTAMENTO]] -> 1903.85 | O24: 0 | P24: =IF(Tabela1[[#This Row],[CARGA PARCIAL]]<0,0,Tabela1[[#This Row],[CARGA PARCIAL]])+Tabela1[[#This Row],[REEMBOLSO]] -> 1903.85 | Q24: Cartão ativo
B25: SANDRO BARRETO DE SOUZA | C25: 78021324953 | D25: =_xlfn.XLOOKUP(Tabela1[[#This Row],[CPF]],[1]Funcionário!$B:$B,[1]Funcionário!$H:$H) -> ATIVO | E25: CEF SUL SC | G25: LEANDRO MARCUSSO | H25: EVERSON GAIDSTIECHI | J25: 1167.34 | K25: 4240 | L25: 9 | N25: =Tabela1[[#This Row],[1QZ DE ABRIL 26]]-Tabela1[[#This Row],[SALDO FINAL]]-Tabela1[[#This Row],[SALDO CARTAO]]-Tabela1[[#This Row],[ADIANTAMENTO]] -> 3063.66 | O25: 0 | P25: =IF(Tabela1[[#This Row],[CARGA PARCIAL]]<0,0,Tabela1[[#This Row],[CARGA PARCIAL]])+Tabela1[[#This Row],[REEMBOLSO]] -> 3063.66 | Q25: Cartão ativo
B26: CHARLES NEVES MATTIUZZI | C26: 12547938790 | D26: =_xlfn.XLOOKUP(Tabela1[[#This Row],[CPF]],[1]Funcionário!$B:$B,[1]Funcionário!$H:$H) -> ATIVO | E26: TELEFONICA ES | G26: VINICIUS LOCATELLY | H26: MARCOS CARIAS | J26: 3430.11 | K26: 4200 | L26: 19.73 | N26: =Tabela1[[#This Row],[1QZ DE ABRIL 26]]-Tabela1[[#This Row],[SALDO FINAL]]-Tabela1[[#This Row],[SALDO CARTAO]]-Tabela1[[#This Row],[ADIANTAMENTO]] -> 750.16 | O26: 0 | P26: =IF(Tabela1[[#This Row],[CARGA PARCIAL]]<0,0,Tabela1[[#This Row],[CARGA PARCIAL]])+Tabela1[[#This Row],[REEMBOLSO]] -> 750.16 | Q26: Cartão ativo
B27: CARLOS NASCIMENTO NONATO JUNIOR | C27: 65973500225 | D27: =_xlfn.XLOOKUP(Tabela1[[#This Row],[CPF]],[1]Funcionário!$B:$B,[1]Funcionário!$H:$H) -> ATIVO | E27: CEF AM AC RR | G27: ANGELICA SOARES | H27: ROGERIO SCATAMBULO | J27: 7077.32 | K27: 4000 | L27: 582.28 | N27: =Tabela1[[#This Row],[1QZ DE ABRIL 26]]-Tabela1[[#This Row],[SALDO FINAL]]-Tabela1[[#This Row],[SALDO CARTAO]]-Tabela1[[#This Row],[ADIANTAMENTO]] -> -3659.6 | O27: 0 | P27: =IF(Tabela1[[#This Row],[CARGA PARCIAL]]<0,0,Tabela1[[#This Row],[CARGA PARCIAL]])+Tabela1[[#This Row],[REEMBOLSO]] -> 0 | Q27: Cartão ativo
B28: EDUARDO ANDREY VENSON SILVA | C28: 02960685946 | D28: =_xlfn.XLOOKUP(Tabela1[[#This Row],[CPF]],[1]Funcionário!$B:$B,[1]Funcionário!$H:$H) -> ATIVO | E28: CEF OESTE SC | G28: LEANDRO MARCUSSO | H28: EVERSON GAIDSTIECHI | I28: -743.83 | J28: 0 | K28: 4000 | L28: 14.73 | N28: =Tabela1[[#This Row],[1QZ DE ABRIL 26]]-Tabela1[[#This Row],[SALDO FINAL]]-Tabela1[[#This Row],[SALDO CARTAO]]-Tabela1[[#This Row],[ADIANTAMENTO]] -> 3985.27 | O28: 0 | P28: =IF(Tabela1[[#This Row],[CARGA PARCIAL]]<0,0,Tabela1[[#This Row],[CARGA PARCIAL]])+Tabela1[[#This Row],[REEMBOLSO]] -> 3985.27 | Q28: Cartão ativo
B29: ENZIO CARVALHO DA MOTA | C29: 38548259515 | D29: =_xlfn.XLOOKUP(Tabela1[[#This Row],[CPF]],[1]Funcionário!$B:$B,[1]Funcionário!$H:$H) -> ATIVO | E29: TELEFONICA BA | G29: GERSON OLIVEIRA | H29: ROGERIO SCATAMBULO | J29: 2472.9 | K29: 4000 | L29: 16.21 | N29: =Tabela1[[#This Row],[1QZ DE ABRIL 26]]-Tabela1[[#This Row],[SALDO FINAL]]-Tabela1[[#This Row],[SALDO CARTAO]]-Tabela1[[#This Row],[ADIANTAMENTO]] -> 1510.89 | O29: 0 | P29: =IF(Tabela1[[#This Row],[CARGA PARCIAL]]<0,0,Tabela1[[#This Row],[CARGA PARCIAL]])+Tabela1[[#This Row],[REEMBOLSO]] -> 1510.89 | Q29: Cartão ativo
B30: FRANCIELLY FELIX CAVALCANTE DE ANDRADE | C30: 09276240446 | D30: =_xlfn.XLOOKUP(Tabela1[[#This Row],[CPF]],[1]Funcionário!$B:$B,[1]Funcionário!$H:$H) -> ATIVO | E30: CEF AM AC RR | G30: ANGELICA SOARES | H30: ROGERIO SCATAMBULO | J30: 798.78 | K30: 4000 | L30: 4002 | N30: =Tabela1[[#This Row],[1QZ DE ABRIL 26]]-Tabela1[[#This Row],[SALDO FINAL]]-Tabela1[[#This Row],[SALDO CARTAO]]-Tabela1[[#This Row],[ADIANTAMENTO]] -> -800.78 | O30: 0 | P30: =IF(Tabela1[[#This Row],[CARGA PARCIAL]]<0,0,Tabela1[[#This Row],[CARGA PARCIAL]])+Tabela1[[#This Row],[REEMBOLSO]] -> 0 | Q30: Cartão ativo
B31: LEANDRO FIGUEREDO BELCHIOR | C31: 26513583802 | D31: =_xlfn.XLOOKUP(Tabela1[[#This Row],[CPF]],[1]Funcionário!$B:$B,[1]Funcionário!$H:$H) -> ATIVO | E31: INSS SP | G31: LEANDRO NUNES | H31: EVERSON GAIDSTIECHI | J31: 2786.98 | K31: 4000 | L31: 1213.02 | N31: =Tabela1[[#This Row],[1QZ DE ABRIL 26]]-Tabela1[[#This Row],[SALDO FINAL]]-Tabela1[[#This Row],[SALDO CARTAO]]-Tabela1[[#This Row],[ADIANTAMENTO]] -> -1.8189894e-12 | O31: 0 | P31: =IF(Tabela1[[#This Row],[CARGA PARCIAL]]<0,0,Tabela1[[#This Row],[CARGA PARCIAL]])+Tabela1[[#This Row],[REEMBOLSO]] -> 0 | Q31: Cartão ativo
B32: LUCIANO JOSE DO AMARAL PEREIRA | C32: 04434355708 | D32: =_xlfn.XLOOKUP(Tabela1[[#This Row],[CPF]],[1]Funcionário!$B:$B,[1]Funcionário!$H:$H) -> ATIVO | E32: CEF CENTRO NORTE SUL RJ | G32: ALLAN JEFFERSON | H32: ROGERIO SCATAMBULO | J32: 3591.91 | K32: 4000 | L32: 49.52 | N32: =Tabela1[[#This Row],[1QZ DE ABRIL 26]]-Tabela1[[#This Row],[SALDO FINAL]]-Tabela1[[#This Row],[SALDO CARTAO]]-Tabela1[[#This Row],[ADIANTAMENTO]] -> 358.57 | O32: 0 | P32: =IF(Tabela1[[#This Row],[CARGA PARCIAL]]<0,0,Tabela1[[#This Row],[CARGA PARCIAL]])+Tabela1[[#This Row],[REEMBOLSO]] -> 358.57 | Q32: Cartão ativo
B33: ORESTE BARBOSA DA SILVA JUNIOR | C33: 25075562850 | D33: =_xlfn.XLOOKUP(Tabela1[[#This Row],[CPF]],[1]Funcionário!$B:$B,[1]Funcionário!$H:$H) -> ATIVO | E33: CEF PIRACICABA SP | G33: LEANDRO NUNES | H33: EVERSON GAIDSTIECHI | I33: -2304.48 | J33: 0 | K33: 4000 | L33: 2.15 | N33: =Tabela1[[#This Row],[1QZ DE ABRIL 26]]-Tabela1[[#This Row],[SALDO FINAL]]-Tabela1[[#This Row],[SALDO CARTAO]]-Tabela1[[#This Row],[ADIANTAMENTO]] -> 3997.85 | O33: 0 | P33: =IF(Tabela1[[#This Row],[CARGA PARCIAL]]<0,0,Tabela1[[#This Row],[CARGA PARCIAL]])+Tabela1[[#This Row],[REEMBOLSO]] -> 3997.85 | Q33: Cartão ativo
B34: RONALDO RUFINO SANTANA | C34: 29758827855 | D34: =_xlfn.XLOOKUP(Tabela1[[#This Row],[CPF]],[1]Funcionário!$B:$B,[1]Funcionário!$H:$H) -> ATIVO | E34: CEF PIRACICABA SP | G34: LEANDRO NUNES | H34: EVERSON GAIDSTIECHI | I34: -927.02 | J34: 0 | K34: 4000 | L34: 6.59 | N34: =Tabela1[[#This Row],[1QZ DE ABRIL 26]]-Tabela1[[#This Row],[SALDO FINAL]]-Tabela1[[#This Row],[SALDO CARTAO]]-Tabela1[[#This Row],[ADIANTAMENTO]] -> 3993.41 | O34: 0 | P34: =IF(Tabela1[[#This Row],[CARGA PARCIAL]]<0,0,Tabela1[[#This Row],[CARGA PARCIAL]])+Tabela1[[#This Row],[REEMBOLSO]] -> 3993.41 | Q34: Cartão ativo
B35: SANDRO CAPISTRANO | C35: 16996346886 | D35: =_xlfn.XLOOKUP(Tabela1[[#This Row],[CPF]],[1]Funcionário!$B:$B,[1]Funcionário!$H:$H) -> ATIVO | E35: CEF BAURU SP | G35: LEANDRO NUNES | H35: EVERSON GAIDSTIECHI | J35: 3452.98 | K35: 4000 | L35: 15.15 | N35: =Tabela1[[#This Row],[1QZ DE ABRIL 26]]-Tabela1[[#This Row],[SALDO FINAL]]-Tabela1[[#This Row],[SALDO CARTAO]]-Tabela1[[#This Row],[ADIANTAMENTO]] -> 531.87 | O35: 0 | P35: =IF(Tabela1[[#This Row],[CARGA PARCIAL]]<0,0,Tabela1[[#This Row],[CARGA PARCIAL]])+Tabela1[[#This Row],[REEMBOLSO]] -> 531.87 | Q35: Cartão ativo
B36: TERCILA DA SILVA LOPES | C36: 67752721387 | D36: =_xlfn.XLOOKUP(Tabela1[[#This Row],[CPF]],[1]Funcionário!$B:$B,[1]Funcionário!$H:$H) -> ATIVO | E36: CEF CEARA | G36: GERSON OLIVEIRA | H36: ROGERIO SCATAMBULO | J36: 4162.21 | K36: 4000 | L36: 1.42 | N36: =Tabela1[[#This Row],[1QZ DE ABRIL 26]]-Tabela1[[#This Row],[SALDO FINAL]]-Tabela1[[#This Row],[SALDO CARTAO]]-Tabela1[[#This Row],[ADIANTAMENTO]] -> -163.63 | O36: 0 | P36: =IF(Tabela1[[#This Row],[CARGA PARCIAL]]<0,0,Tabela1[[#This Row],[CARGA PARCIAL]])+Tabela1[[#This Row],[REEMBOLSO]] -> 0 | Q36: Cartão ativo
B37: UBIRAJARA DE ARAUJO TEIXEIRA | C37: 74548565949 | D37: =_xlfn.XLOOKUP(Tabela1[[#This Row],[CPF]],[1]Funcionário!$B:$B,[1]Funcionário!$H:$H) -> ATIVO | E37: BB APOIO PR | G37: LEANDRO MARCUSSO | H37: EVERSON GAIDSTIECHI | J37: 3920.17 | K37: 4000 | L37: 6.94 | N37: =Tabela1[[#This Row],[1QZ DE ABRIL 26]]-Tabela1[[#This Row],[SALDO FINAL]]-Tabela1[[#This Row],[SALDO CARTAO]]-Tabela1[[#This Row],[ADIANTAMENTO]] -> 72.89 | O37: 0 | P37: =IF(Tabela1[[#This Row],[CARGA PARCIAL]]<0,0,Tabela1[[#This Row],[CARGA PARCIAL]])+Tabela1[[#This Row],[REEMBOLSO]] -> 72.89 | Q37: Cartão ativo
B38: CAIO FRANCESCONI RIBEIRO | C38: 08924586904 | D38: =_xlfn.XLOOKUP(Tabela1[[#This Row],[CPF]],[1]Funcionário!$B:$B,[1]Funcionário!$H:$H) -> ATIVO | E38: TJ APOIO PR | G38: LEANDRO MARCUSSO | H38: EVERSON GAIDSTIECHI | J38: 6499.38 | K38: 3900 | L38: 4.82 | N38: =Tabela1[[#This Row],[1QZ DE ABRIL 26]]-Tabela1[[#This Row],[SALDO FINAL]]-Tabela1[[#This Row],[SALDO CARTAO]]-Tabela1[[#This Row],[ADIANTAMENTO]] -> -2604.2 | O38: 0 | P38: =IF(Tabela1[[#This Row],[CARGA PARCIAL]]<0,0,Tabela1[[#This Row],[CARGA PARCIAL]])+Tabela1[[#This Row],[REEMBOLSO]] -> 0 | Q38: Cartão ativo
B39: MICHAEL RODRIGUES SANTOS | C39: 37425574837 | D39: =_xlfn.XLOOKUP(Tabela1[[#This Row],[CPF]],[1]Funcionário!$B:$B,[1]Funcionário!$H:$H) -> ATIVO | E39: CEF SP SUL | G39: LEANDRO NUNES | H39: EVERSON GAIDSTIECHI | J39: 1798.56 | K39: 3350 | L39: 2 | N39: =Tabela1[[#This Row],[1QZ DE ABRIL 26]]-Tabela1[[#This Row],[SALDO FINAL]]-Tabela1[[#This Row],[SALDO CARTAO]]-Tabela1[[#This Row],[ADIANTAMENTO]] -> 1549.44 | O39: 0 | P39: =IF(Tabela1[[#This Row],[CARGA PARCIAL]]<0,0,Tabela1[[#This Row],[CARGA PARCIAL]])+Tabela1[[#This Row],[REEMBOLSO]] -> 1549.44 | Q39: Cartão ativo
B40: FERNANDO RODRIGUES DUARTE | C40: 03377983112 | D40: =_xlfn.XLOOKUP(Tabela1[[#This Row],[CPF]],[1]Funcionário!$B:$B,[1]Funcionário!$H:$H) -> ATIVO | E40: CLARO CO | G40: ANGELICA SOARES | H40: ROGERIO SCATAMBULO | J40: 553.39 | K40: 3200 | L40: 2 | N40: =Tabela1[[#This Row],[1QZ DE ABRIL 26]]-Tabela1[[#This Row],[SALDO FINAL]]-Tabela1[[#This Row],[SALDO CARTAO]]-Tabela1[[#This Row],[ADIANTAMENTO]] -> 2644.61 | O40: 0 | P40: =IF(Tabela1[[#This Row],[CARGA PARCIAL]]<0,0,Tabela1[[#This Row],[CARGA PARCIAL]])+Tabela1[[#This Row],[REEMBOLSO]] -> 2644.61 | Q40: Cartão ativo
B41: ALESSANDRO DE OLIVEIRA AZEVEDO | C41: 27494577858 | D41: =_xlfn.XLOOKUP(Tabela1[[#This Row],[CPF]],[1]Funcionário!$B:$B,[1]Funcionário!$H:$H) -> ATIVO | E41: CEF BAURU SP | G41: LEANDRO NUNES | H41: EVERSON GAIDSTIECHI | I41: -807.61 | J41: 0 | K41: 3000 | L41: 337.99 | N41: =Tabela1[[#This Row],[1QZ DE ABRIL 26]]-Tabela1[[#This Row],[SALDO FINAL]]-Tabela1[[#This Row],[SALDO CARTAO]]-Tabela1[[#This Row],[ADIANTAMENTO]] -> 2662.01 | O41: 0 | P41: =IF(Tabela1[[#This Row],[CARGA PARCIAL]]<0,0,Tabela1[[#This Row],[CARGA PARCIAL]])+Tabela1[[#This Row],[REEMBOLSO]] -> 2662.01 | Q41: Cartão ativo
B42: CLERITON BACILA DOS SANTOS | C42: 05456615959 | D42: =_xlfn.XLOOKUP(Tabela1[[#This Row],[CPF]],[1]Funcionário!$B:$B,[1]Funcionário!$H:$H) -> ATIVO | E42: NET CTA PR | G42: LEANDRO MARCUSSO | H42: EVERSON GAIDSTIECHI | J42: 4815.38 | K42: 3000 | L42: 1087.63 | N42: =Tabela1[[#This Row],[1QZ DE ABRIL 26]]-Tabela1[[#This Row],[SALDO FINAL]]-Tabela1[[#This Row],[SALDO CARTAO]]-Tabela1[[#This Row],[ADIANTAMENTO]] -> -2903.01 | O42: 0 | P42: =IF(Tabela1[[#This Row],[CARGA PARCIAL]]<0,0,Tabela1[[#This Row],[CARGA PARCIAL]])+Tabela1[[#This Row],[REEMBOLSO]] -> 0 | Q42: Cartão ativo
B43: EMERSON LEITE DE BARROS | C43: 34168918807 | D43: =_xlfn.XLOOKUP(Tabela1[[#This Row],[CPF]],[1]Funcionário!$B:$B,[1]Funcionário!$H:$H) -> ATIVO | E43: PTB INFRA SUDESTE | G43: LEANDRO NUNES | H43: EVERSON GAIDSTIECHI | I43: -2799.19 | J43: 0 | K43: 3000 | L43: 0 | N43: =Tabela1[[#This Row],[1QZ DE ABRIL 26]]-Tabela1[[#This Row],[SALDO FINAL]]-Tabela1[[#This Row],[SALDO CARTAO]]-Tabela1[[#This Row],[ADIANTAMENTO]] -> 3000 | O43: 2800 | P43: =IF(Tabela1[[#This Row],[CARGA PARCIAL]]<0,0,Tabela1[[#This Row],[CARGA PARCIAL]])+Tabela1[[#This Row],[REEMBOLSO]] -> 5800 | Q43: Cartão ativo
B44: JESSICA DE MIRANDA MEDEIROS FELICIANO | C44: 10137575483 | D44: =_xlfn.XLOOKUP(Tabela1[[#This Row],[CPF]],[1]Funcionário!$B:$B,[1]Funcionário!$H:$H) -> ATIVO | E44: CEF PIRACICABA SP | G44: LEANDRO NUNES | H44: EVERSON GAIDSTIECHI | I44: -4.35 | J44: 0 | K44: 3000 | L44: 6.58 | N44: =Tabela1[[#This Row],[1QZ DE ABRIL 26]]-Tabela1[[#This Row],[SALDO FINAL]]-Tabela1[[#This Row],[SALDO CARTAO]]-Tabela1[[#This Row],[ADIANTAMENTO]] -> 2993.42 | O44: 0 | P44: =IF(Tabela1[[#This Row],[CARGA PARCIAL]]<0,0,Tabela1[[#This Row],[CARGA PARCIAL]])+Tabela1[[#This Row],[REEMBOLSO]] -> 2993.42 | Q44: Cartão ativo
...

Sheet Planilha3
B2: Cobrança | C2: Nome | D2: E-mail | E2: Tipo de usuário | F2: Status do Cartão | G2: Permissão de Uso | H2: Permissão de Gestão | I2: Ações
C3: ABNER ANDRADE CAVALCANTE | D3: abner.cavalcante@eqsengenharia.com.br | E3: Normal | F3: Cartão ativo | G3: Portador de Cartão | H3: Sem permissão
C4: ADAN LEONARDO SOUZA BATISTA | D4: adan.batista@eqsengenharia.com.br | E4: Normal | F4: Cartão ativo | G4: Portador de Cartão | H4: Sem permissão
C5: ADAUTO JOSE PEREIRA | D5: adautojosepereira@yahoo.com.br | E5: Normal | F5: Cartão ativo | G5: Portador de Cartão | H5: Sem permissão
C6: ADEMARCIO DUARTE LOPES | D6: ctba_projetos@hotmail.com | E6: Normal | F6: Cartão ativo | G6: Portador de Cartão | H6: Sem permissão
C7: ADILSON ANTONIO JACINTO | D7: dirson4867@yahoo.com | E7: Normal | F7: Cartão ativo | G7: Portador de Cartão | H7: Sem permissão
C8: ADILSON MELLO DE CAMARGO | D8: adilsoncamargo@eqseng.com.br | E8: Normal | F8: Cartão ativo | G8: Portador de Cartão | H8: Sem permissão
C9: ADILSON RODRIGUES FERREIRA | D9: adilson.ferreira@eqsengenharia.com.br | E9: Intermediário | F9: Cadastro pendente | G9: Portador de Cartão | H9: Sem permissão
C10: ADIVAR ANTONIO DA SILVA JUNIOR | D10: adivarjunior@gmail.com | E10: Normal | F10: Cartão ativo | G10: Portador de Cartão | H10: Sem permissão
C11: ADMILSON DA SILVA FARIAS | D11: admilsonfarias2016@gmail.com | E11: Normal | F11: Cadastro pendente | G11: Portador de Cartão | H11: Sem permissão
C12: ADMILSON DOS SANTOS GALAN | D12: admilsongalan@gmail.com | E12: Normal | F12: Cartão ativo | G12: Portador de Cartão | H12: Sem permissão
C13: ADRIANA DA CONCEICAO PEREIRA DE MELO | D13: adriana.melo@eqsengenharia.com.br | E13: Normal | F13: Cadastro pendente | G13: Portador de Cartão | H13: Sem permissão
C14: ADRIANE CARON | D14: adriane.caron@eqseng.com.br | E14: Normal | F14: Cartão ativo | G14: Portador de Cartão | H14: Sem permissão
... C435: MELSO CEZAR DA SILVA NETO | D435: melsocezar@gmail.com | E435: Normal | F435: Cartão ativo | G435: Portador de Cartão | H435: Sem permissão
C436: MELSO CEZAR DA SILVA NETO
C437: MICHAEL RODRIGUES SANTOS | D437: michael.santos@eqseng.com.br | E437: Normal | F437: Cartão ativo | G437: Portador de Cartão | H437: Sem permissão
C438: MICHEL DOS SANTOS VENANCIO | D438: michel.venancio29@gmail.com | E438: Normal | F438: Cartão ativo | G438: Portador de Cartão | H438: Sem permissão
C439: MICHEL VINHORTE DE SOUZA | D439: michellmvs@gmail.com | E439: Normal | F439: Cartão ativo | G439: Portador de Cartão | H439: Sem permissão
C440: MIGUEL JOAO DINIS MOTA | D440: mjdmota@gmail.com | E440: Normal | F440: Cartão ativo | G440: Portador de Cartão | H440: Sem permissão
C441: MILTON BRASIL CAVALCANTE | D441: v.tiomilton@gmail.com | E441: Normal | F441: Cadastro pendente | G441: Portador de Cartão | H441: Sem permissão
C442: MILTON FERREIRA DAS NEVES JUNIOR | D442: milton.neves@eqsengenharia.com.br | E442: Normal | F442: Cartão ativo | G442: Portador de Cartão | H442: Sem permissão
C443: MILTON FLECK PITROWSKI | D443: milton.pitrowski@eqseng.com.br | E443: Normal | F443: Cartão ativo | G443: Portador de Cartão | H443: Sem permissão
C444: MOISES DOS SANTOS CABRAL | D444: moises.cabral@eqsengenharia.com.br | E444: Normal | F444: Cartão ativo | G444: Portador de Cartão | H444: Sem permissão
C445: MURILO DE ALMEIDA | D445: murilo.almeida@eqsengenharia.com.br | E445: Normal | F445: Cartão ativo | G445: Portador de Cartão | H445: Sem permissão
C446: NELSON FILIPE MARTINS DA SILVA | D446: nelsonfilipe316@gmail.com | E446: Normal | F446: Cartão ativo | G446: Portador de Cartão | H446: Sem permissão
C447: NERTAN DE CASTRO MAIA | D447: nertancastromaia@gmail.com | E447: Normal | F447: Cartão ativo | G447: Portador de Cartão | H447: Sem permissão
C448: NEUDO SAMPIETRO | D448: neudoengeman@gmail.com | E448: Normal | F448: Cartão ativo | G448: Portador de Cartão | H448: Sem permissão
... C597: WILSON LUIZ CABRAL | D597: wilson.cabral@eqsengenharia.com.br | E597: Normal | F597: Cartão ativo | G597: Portador de Cartão | H597: Sem permissão
B598: Página 12 de 12
B599: Itens por página:
B600: 50

Sheet Planilha2
B2: Cobrança | C2: Nome | D2: E-mail | E2: Tipo de usuário | F2: Status do Cartão | G2: Permissão de Uso | H2: Permissão de Gestão | I2: Ações
C3: ABNER ANDRADE CAVALCANTE | D3: abner.cavalcante@eqsengenharia.com.br | E3: Normal | F3: Cartão ativo | G3: Portador de Cartão | H3: Sem permissão
C4: ADAN LEONARDO SOUZA BATISTA | D4: adan.batista@eqsengenharia.com.br | E4: Normal | F4: Cartão ativo | G4: Portador de Cartão | H4: Sem permissão
C5: ADAUTO JOSE PEREIRA | D5: adautojosepereira@yahoo.com.br | E5: Normal | F5: Cartão ativo | G5: Portador de Cartão | H5: Sem permissão
C6: ADEMARCIO DUARTE LOPES | D6: ctba_projetos@hotmail.com | E6: Normal | F6: Cartão ativo | G6: Portador de Cartão | H6: Sem permissão
C7: ADILSON MELLO DE CAMARGO | D7: adilsoncamargo@eqseng.com.br | E7: Normal | F7: Cartão ativo | G7: Portador de Cartão | H7: Sem permissão
C8: ADILSON RODRIGUES FERREIRA | D8: adilson.ferreira@eqsengenharia.com.br | E8: Intermediário | F8: Cadastro pendente | G8: Portador de Cartão | H8: Sem permissão
C9: ADIVAR ANTONIO DA SILVA JUNIOR | D9: adivarjunior@gmail.com | E9: Normal | F9: Cartão ativo | G9: Portador de Cartão | H9: Sem permissão
C10: ADMILSON DOS SANTOS GALAN | D10: admilsongalan@gmail.com | E10: Normal | F10: Cartão ativo | G10: Portador de Cartão | H10: Sem permissão
C11: ADRIANE CARON | D11: caronjca@gmail.com | E11: Normal | F11: Cadastro pendente | G11: Portador de Cartão | H11: Sem permissão
C12: ADRIANO BORGES TEIXEIRA | D12: adrianoteixeiraeletricista@gmail.com | E12: Normal | F12: Cartão não vinculado | G12: Portador de Cartão | H12: Sem permissão
C13: ADRIANO FRANCISCO DE PAULA | D13: adriano.paula@eqsengenharia.com.br | E13: Normal | F13: Cartão ativo | G13: Portador de Cartão | H13: Sem permissão
C14: ADSON ARAUJO DA SILVA | D14: adson.silva@eqsengenharia.com.br | E14: Normal | F14: Cartão ativo | G14: Portador de Cartão | H14: Sem permissão
... C543: WILSON LUIZ CABRAL | D543: wilson.cabral@eqsengenharia.com.br | E543: Normal | F543: Cartão ativo | G543: Portador de Cartão | H543: Sem permissão

Sheet Planilha1
B1: Cobrança | C1: Nome | D1: E-mail | E1: Tipo de usuário | F1: Status do Cartão | G1: Permissão de Uso | H1: Permissão de Gestão | I1: Ações
C2: ABNER ANDRADE CAVALCANTE | D2: abner.cavalcante@eqsengenharia.com.br | E2: Normal | F2: Cartão ativo | G2: Portador de Cartão | H2: Sem permissão
C3: ADAN LEONARDO SOUZA BATISTA | D3: adan.batista@eqsengenharia.com.br | E3: Normal | F3: Cartão ativo | G3: Portador de Cartão | H3: Sem permissão
C4: ADAUTO JOSE PEREIRA | D4: adautojosepereira@yahoo.com.br | E4: Normal | F4: Cartão ativo | G4: Portador de Cartão | H4: Sem permissão
C5: ADEMARCIO DUARTE LOPES | D5: ctba_projetos@hotmail.com | E5: Normal | F5: Cartão ativo | G5: Portador de Cartão | H5: Sem permissão
C6: ADILSON MELLO DE CAMARGO | D6: adilsoncamargo@eqseng.com.br | E6: Normal | F6: Cartão ativo | G6: Portador de Cartão | H6: Sem permissão
C7: ADILSON RODRIGUES FERREIRA | D7: adilson.ferreira@eqsengenharia.com.br | E7: Intermediário | F7: Cadastro pendente | G7: Portador de Cartão | H7: Sem permissão
C8: ADIVAR ANTONIO DA SILVA JUNIOR | D8: adivarjunior@gmail.com | E8: Normal | F8: Cartão ativo | G8: Portador de Cartão | H8: Sem permissão
C9: ADMILSON DOS SANTOS GALAN | D9: admilsongalan@gmail.com | E9: Normal | F9: Cartão ativo | G9: Portador de Cartão | H9: Sem permissão
C10: ADRIANE CARON | D10: caronjca@gmail.com | E10: Normal | F10: Cadastro pendente | G10: Portador de Cartão | H10: Sem permissão
C11: ADRIANO BORGES TEIXEIRA | D11: adrianoteixeiraeletricista@gmail.com | E11: Normal | F11: Cartão não vinculado | G11: Portador de Cartão | H11: Sem permissão
C12: ADRIANO FRANCISCO DE PAULA | D12: adriano.paula@eqsengenharia.com.br | E12: Normal | F12: Cartão ativo | G12: Portador de Cartão | H12: Sem permissão
C13: ADSON ARAUJO DA SILVA | D13: adson.silva@eqsengenharia.com.br | E13: Normal | F13: Cartão ativo | G13: Portador de Cartão | H13: Sem permissão
... C532: JOSE DO PRADO ROSA | D532: zepradoeqs@gmail.com | E532: Normal | F532: Cartão ativo | G532: Portador de Cartão | H532: Sem permissão

Sheet VALIDAÇÃO AGILLITAS
A1: PORTADOR | C1: CARTÃO | D1: AGILLITAS | E1: Situação cpf | F1: situação nome | G1: CARTAO VALIDACAO
A2: ABNER ANDRADE CAVALCANTE | B2: 02027745203 | C2: AGILLITAS | D2: 9042407399982 | E2: ATIVO | F2: ATIVO | G2: AGILLITAS
A3: JAEDER RODRIGUES JUNIOR | B3: 07505987607 | C3: AGILLITAS | D3: 9042408249079 | E3: ATIVO | F3: ATIVO | G3: AGILLITAS
A4: THIAGO DE MEDEIROS VANZELER | B4: 11590627733 | C4: AGILLITAS | D4: 9042407080491 | E4: ATIVO | F4: ATIVO | G4: AGILLITAS
A5: JOSE ROBERTO DA SILVA FREIRE | B5: 54229464134 | C5: AGILLITAS | D5: 9042406782287 | E5: ATIVO | F5: #N/A | G5: AGILLITAS
A6: WALTER DE CAMPOS NUNES NETO | B6: 99114160030 | C6: AGILLITAS | D6: 9042408803396 | E6: ATIVO | F6: ATIVO | G6: AGILLITAS
A7: JUAN CARLOS PANTOJA AMANAJAS | B7: 51027941249 | C7: AGILLITAS | D7: - | E7: ATIVO | F7: INATIVO | G7: AGILLITAS
A8: LUDGERO HORACIO DE OLIVEIRA | B8: 06576198922 | C8: AGILLITAS | D8: 9042407986861 | E8: ATIVO | F8: ATIVO | G8: AGILLITAS
A9: CARLOS NASCIMENTO NONATO JUNIOR | B9: 65973500225 | C9: AGILLITAS | D9: 9042406782022 | E9: ATIVO | F9: ATIVO | G9: AGILLITAS
A10: MICHAEL RODRIGUES SANTOS | B10: 37425574837 | C10: AGILLITAS | D10: 9042407400145 | E10: ATIVO | F10: ATIVO | G10: AGILLITAS
A11: FLAVIO FERNANDES DOS REIS LIMA | B11: 01767960107 | C11: AGILLITAS | D11: 9042408803750 | E11: ATIVO | F11: ATIVO | G11: AGILLITAS
A12: VICTOR SIGOLO PINHEIRO PIMENTA | B12: 12237490619 | C12: AGILLITAS | D12: 9076505613050 | E12: ATIVO | F12: ATIVO | G12: AGILLITAS
A13: JOSE CLAUDIO RIBEIRO | B13: 61158852649 | C13: AGILLITAS | D13: 9042408803859 | E13: ATIVO | F13: ATIVO | G13: AGILLITAS
A14: LEUSAFFAN GUSTAVO DE SIQUEIRA | B14: 09502929667 | C14: AGILLITAS | D14: #N/A | E14: #N/A | F14: #N/A | G14: #N/A
A15: FABIO DIOGO BITTENCOURT | B15: 00526143959 | C15: AGILLITAS | D15: 9042408970526 | E15: ATIVO | F15: ATIVO | G15: AGILLITAS
A16: LEANDRO FIGUEREDO BELCHIOR | B16: 26513583802 | C16: AGILLITAS | D16: 9042408599341 | E16: ATIVO | F16: ATIVO | G16: AGILLITAS
A17: BRUNO OLIVEIRA DIAS | B17: 11992259755 | C17: AGILLITAS | D17: 9042408803735 | E17: ATIVO | F17: #N/A | G17: AGILLITAS
A18: ANDRE LUIZ SANTANA | B18: 11897381638 | C18: AGILLITAS | D18: 9042408249145 | E18: ATIVO | F18: ATIVO | G18: AGILLITAS
A19: CARLOS EDUARDO SCATAMBULO | B19: 22730778829 | C19: AGILLITAS | D19: 9042406781958 | E19: ATIVO | F19: ATIVO | G19: AGILLITAS
A20: GUILHERME BATISTA DA SILVA | B20: 14829137711 | C20: AGILLITAS | D20: 9076509301751 | E20: ATIVO | F20: ATIVO | G20: AGILLITAS
A21: MARCO AURELIO DE LIMA | B21: 01356318665 | C21: AGILLITAS | D21: 9042408970203 | E21: ATIVO | F21: ATIVO | G21: AGILLITAS
A22: EDINALDO LEAL DE SOUZA | B22: 82277206172 | C22: AGILLITAS | D22: 9042408803305 | E22: ATIVO | F22: ATIVO | G22: AGILLITAS
A23: NEDSON LUIZ DURAES VELOSO | B23: 11498112692 | C23: AGILLITAS | D23: 9042407080285 | E23: ATIVO | F23: ATIVO | G23: AGILLITAS
A24: CLERITON BACILA DOS SANTOS | B24: 05456615959 | C24: AGILLITAS | D24: 9042406782311 | E24: ATIVO | F24: ATIVO | G24: AGILLITAS
A25: JOELSON FERREIRA DOS SANTOS | B25: 07690263623 | C25: AGILLITAS | D25: 9042406781990 | E25: ATIVO | F25: #N/A | G25: AGILLITAS
A26: ISA CARLA DE OLIVEIRA LOPES | B26: 06085235429 | C26: AGILLITAS | D26: #N/A | E26: #N/A | F26: #N/A | G26: #N/A
A27: RENATO DIAS DOS SANTOS | B27: 03498210114 | C27: AGILLITAS | D27: #N/A | E27: #N/A | F27: #N/A | G27: #N/A
A28: EDUARDO SANTOS | B28: 91270529072 | C28: AGILLITAS | D28: 9042407752073 | E28: ATIVO | F28: ATIVO | G28: AGILLITAS
A29: SAULO ARAUJO DE PAULA | B29: 31040091806 | C29: AGILLITAS | D29: 9042407552176 | E29: ATIVO | F29: ATIVO | G29: AGILLITAS
A30: ANGELICA APARECIDA DOS SANTOS | B30: 34857901846 | C30: AGILLITAS | D30: 9042408803891 | E30: ATIVO | F30: ATIVO | G30: AGILLITAS
A31: DANIEL DA SILVA LOPES | B31: 94288259053 | C31: AGILLITAS | D31: 9042407552085 | E31: ATIVO | F31: ATIVO | G31: FLASH
A32: VINICIUS ALVES VIEIRA | B32: EXCLUIR | C32: AGILLITAS | D32: #N/A | E32: #N/A | F32: #N/A | G32: #N/A
A33: CARLOS AUGUSTO ALVES CAVALCANTI | B33: EXCLUIR | C33: AGILLITAS | D33: #N/A | E33: #N/A | F33: #N/A | G33: #N/A
A34: ANDRESA INDIRA SANTANA AGGIO | B34: EXCLUIR | C34: AGILLITAS | D34: #N/A | E34: #N/A | F34: #N/A | G34: #N/A
A35: RODRIGO BOLDO | B35: 27104988807 | C35: AGILLITAS | D35: 9042408599291 | E35: ATIVO | F35: ATIVO | G35: AGILLITAS
A36: EMERSON LEITE DE BARROS | B36: 34168918807 | C36: AGILLITAS | D36: 9042408340399 | E36: ATIVO | F36: ATIVO | G36: AGILLITAS
A37: ANTONIO JOSE PEREIRA DA SILVA | B37: 08326260401 | C37: AGILLITAS | D37: 9042408481813 | E37: ATIVO | F37: ATIVO | G37: AGILLITAS
A38: STEPHANIE THAINARA DE OLIVEIRA ROCHA DA COSTA | B38: 14084321613 | C38: AGILLITAS | D38: 9076505613068 | E38: ATIVO | F38: ATIVO | G38: AGILLITAS
A39: JOSÉ LUIS TERRIBILE | B39: 65009304015 | C39: AGILLITAS | D39: 9042408804113 | E39: ATIVO | F39: ATIVO | G39: AGILLITAS
A40: CLAUDEMIR GREGOSKI RODRIGUES | B40: 05144026958 | C40: AGILLITAS | D40: 9042408970278 | E40: ATIVO | F40: ATIVO | G40: AGILLITAS
...
